2023-06-18 17:01:33,528 ERROR PID 7049 Exception occurred
Traceback (most recent call last):
  File "/home/ichiro/factory-mockup/mockup.py", line 57, in send_data
    sock.connect((MODBUS_IP, MODBUS_PORT))
ConnectionRefusedError: [Errno 111] Connection refused
2023-06-18 17:01:33,540 INFO PID 7049 Playing video file 5.mp4
2023-06-18 17:01:33,725 ERROR PID 7049 Exception occurred
Traceback (most recent call last):
  File "/home/ichiro/factory-mockup/mockup.py", line 57, in send_data
    sock.connect((MODBUS_IP, MODBUS_PORT))
ConnectionRefusedError: [Errno 111] Connection refused
2023-06-18 17:01:44,828 INFO PID 7049 Playing video file 1.mp4
2023-06-18 17:01:44,966 ERROR PID 7049 Exception occurred
Traceback (most recent call last):
  File "/home/ichiro/factory-mockup/mockup.py", line 57, in send_data
    sock.connect((MODBUS_IP, MODBUS_PORT))
ConnectionRefusedError: [Errno 111] Connection refused
2023-06-18 17:01:49,380 INFO PID 7049 Playing video file 1.mp4
2023-06-18 17:01:49,559 ERROR PID 7049 Exception occurred
Traceback (most recent call last):
  File "/home/ichiro/factory-mockup/mockup.py", line 57, in send_data
    sock.connect((MODBUS_IP, MODBUS_PORT))
ConnectionRefusedError: [Errno 111] Connection refused
2023-06-18 17:01:53,411 INFO PID 7049 Playing video file 2.mp4
2023-06-18 17:01:53,570 ERROR PID 7049 Exception occurred
Traceback (most recent call last):
  File "/home/ichiro/factory-mockup/mockup.py", line 57, in send_data
    sock.connect((MODBUS_IP, MODBUS_PORT))
ConnectionRefusedError: [Errno 111] Connection refused
2023-06-18 17:01:59,022 INFO PID 7049 Playing video file 3.mp4
2023-06-18 17:01:59,210 ERROR PID 7049 Exception occurred
Traceback (most recent call last):
  File "/home/ichiro/factory-mockup/mockup.py", line 57, in send_data
    sock.connect((MODBUS_IP, MODBUS_PORT))
ConnectionRefusedError: [Errno 111] Connection refused
2023-06-18 17:02:05,081 INFO PID 7049 Playing video file 5.mp4
2023-06-18 17:02:05,299 ERROR PID 7049 Exception occurred
Traceback (most recent call last):
  File "/home/ichiro/factory-mockup/mockup.py", line 57, in send_data
    sock.connect((MODBUS_IP, MODBUS_PORT))
ConnectionRefusedError: [Errno 111] Connection refused
2023-06-18 17:02:10,107 INFO PID 7049 Playing video file 3.mp4
2023-06-18 17:02:10,232 ERROR PID 7049 Exception occurred
Traceback (most recent call last):
  File "/home/ichiro/factory-mockup/mockup.py", line 57, in send_data
    sock.connect((MODBUS_IP, MODBUS_PORT))
ConnectionRefusedError: [Errno 111] Connection refused
2023-06-18 17:02:15,555 INFO PID 7049 Playing video file 4.mp4
2023-06-18 17:02:15,764 ERROR PID 7049 Exception occurred
Traceback (most recent call last):
  File "/home/ichiro/factory-mockup/mockup.py", line 57, in send_data
    sock.connect((MODBUS_IP, MODBUS_PORT))
ConnectionRefusedError: [Errno 111] Connection refused
2023-06-18 17:02:18,981 INFO PID 7049 Playing video file 5.mp4
2023-06-18 17:02:19,157 ERROR PID 7049 Exception occurred
Traceback (most recent call last):
  File "/home/ichiro/factory-mockup/mockup.py", line 57, in send_data
    sock.connect((MODBUS_IP, MODBUS_PORT))
ConnectionRefusedError: [Errno 111] Connection refused
2023-06-18 17:02:23,534 INFO PID 7049 Playing video file 5.mp4
2023-06-18 17:02:23,726 ERROR PID 7049 Exception occurred
Traceback (most recent call last):
  File "/home/ichiro/factory-mockup/mockup.py", line 57, in send_data
    sock.connect((MODBUS_IP, MODBUS_PORT))
ConnectionRefusedError: [Errno 111] Connection refused
2023-06-18 17:05:11,232 INFO PID 7803 Playing video file 4.mp4
2023-06-18 17:05:11,432 ERROR PID 7803 Exception occurred
Traceback (most recent call last):
  File "/home/ichiro/factory-mockup/mockup.py", line 57, in send_data
    sock.connect((MODBUS_IP, MODBUS_PORT))
ConnectionRefusedError: [Errno 111] Connection refused
2023-06-18 17:05:12,941 INFO PID 7803 Playing video file 5.mp4
2023-06-18 17:05:12,996 ERROR PID 7803 Exception occurred
Traceback (most recent call last):
  File "/home/ichiro/factory-mockup/mockup.py", line 57, in send_data
    sock.connect((MODBUS_IP, MODBUS_PORT))
ConnectionRefusedError: [Errno 111] Connection refused
2023-06-18 17:05:31,535 INFO PID 7803 Playing video file 5.mp4
2023-06-18 17:05:31,596 ERROR PID 7803 Exception occurred
Traceback (most recent call last):
  File "/home/ichiro/factory-mockup/mockup.py", line 57, in send_data
    sock.connect((MODBUS_IP, MODBUS_PORT))
ConnectionRefusedError: [Errno 111] Connection refused
2023-06-18 17:05:33,101 INFO PID 7803 Playing video file 2.mp4
2023-06-18 17:05:33,158 ERROR PID 7803 Exception occurred
Traceback (most recent call last):
  File "/home/ichiro/factory-mockup/mockup.py", line 57, in send_data
    sock.connect((MODBUS_IP, MODBUS_PORT))
ConnectionRefusedError: [Errno 111] Connection refused
2023-06-18 17:05:34,664 INFO PID 7803 Playing video file 5.mp4
2023-06-18 17:05:34,730 ERROR PID 7803 Exception occurred
Traceback (most recent call last):
  File "/home/ichiro/factory-mockup/mockup.py", line 57, in send_data
    sock.connect((MODBUS_IP, MODBUS_PORT))
ConnectionRefusedError: [Errno 111] Connection refused
2023-06-18 17:05:36,236 INFO PID 7803 Playing video file 2.mp4
2023-06-18 17:05:36,300 ERROR PID 7803 Exception occurred
Traceback (most recent call last):
  File "/home/ichiro/factory-mockup/mockup.py", line 57, in send_data
    sock.connect((MODBUS_IP, MODBUS_PORT))
ConnectionRefusedError: [Errno 111] Connection refused
2023-06-18 17:05:37,806 INFO PID 7803 Playing video file 1.mp4
2023-06-18 17:05:37,868 ERROR PID 7803 Exception occurred
Traceback (most recent call last):
  File "/home/ichiro/factory-mockup/mockup.py", line 57, in send_data
    sock.connect((MODBUS_IP, MODBUS_PORT))
ConnectionRefusedError: [Errno 111] Connection refused
2023-06-18 17:05:39,374 INFO PID 7803 Playing video file 3.mp4
2023-06-18 17:05:39,438 ERROR PID 7803 Exception occurred
Traceback (most recent call last):
  File "/home/ichiro/factory-mockup/mockup.py", line 57, in send_data
    sock.connect((MODBUS_IP, MODBUS_PORT))
ConnectionRefusedError: [Errno 111] Connection refused
2023-06-18 17:05:39,944 INFO PID 7803 Playing video file 4.mp4
2023-06-18 17:05:40,013 ERROR PID 7803 Exception occurred
Traceback (most recent call last):
  File "/home/ichiro/factory-mockup/mockup.py", line 57, in send_data
    sock.connect((MODBUS_IP, MODBUS_PORT))
ConnectionRefusedError: [Errno 111] Connection refused
2023-06-18 17:05:41,518 INFO PID 7803 Playing video file 1.mp4
2023-06-18 17:05:41,578 ERROR PID 7803 Exception occurred
Traceback (most recent call last):
  File "/home/ichiro/factory-mockup/mockup.py", line 57, in send_data
    sock.connect((MODBUS_IP, MODBUS_PORT))
ConnectionRefusedError: [Errno 111] Connection refused
2023-06-18 17:05:43,586 INFO PID 7803 Playing video file 4.mp4
2023-06-18 17:05:43,649 ERROR PID 7803 Exception occurred
Traceback (most recent call last):
  File "/home/ichiro/factory-mockup/mockup.py", line 57, in send_data
    sock.connect((MODBUS_IP, MODBUS_PORT))
ConnectionRefusedError: [Errno 111] Connection refused
2023-06-18 17:05:45,154 INFO PID 7803 Playing video file 5.mp4
2023-06-18 17:05:45,205 ERROR PID 7803 Exception occurred
Traceback (most recent call last):
  File "/home/ichiro/factory-mockup/mockup.py", line 57, in send_data
    sock.connect((MODBUS_IP, MODBUS_PORT))
ConnectionRefusedError: [Errno 111] Connection refused
2023-06-18 17:05:47,210 INFO PID 7803 Playing video file 5.mp4
2023-06-18 17:05:47,278 ERROR PID 7803 Exception occurred
Traceback (most recent call last):
  File "/home/ichiro/factory-mockup/mockup.py", line 57, in send_data
    sock.connect((MODBUS_IP, MODBUS_PORT))
ConnectionRefusedError: [Errno 111] Connection refused
2023-06-18 17:05:48,282 INFO PID 7803 Playing video file 3.mp4
2023-06-18 17:05:48,343 ERROR PID 7803 Exception occurred
Traceback (most recent call last):
  File "/home/ichiro/factory-mockup/mockup.py", line 57, in send_data
    sock.connect((MODBUS_IP, MODBUS_PORT))
ConnectionRefusedError: [Errno 111] Connection refused
2023-06-18 17:05:49,850 INFO PID 7803 Playing video file 4.mp4
2023-06-18 17:05:49,927 ERROR PID 7803 Exception occurred
Traceback (most recent call last):
  File "/home/ichiro/factory-mockup/mockup.py", line 57, in send_data
    sock.connect((MODBUS_IP, MODBUS_PORT))
ConnectionRefusedError: [Errno 111] Connection refused
2023-06-18 17:07:23,160 INFO PID 8025 Playing video file 2.mp4
2023-06-18 17:07:23,224 ERROR PID 8025 Exception occurred
Traceback (most recent call last):
  File "/home/ichiro/factory-mockup/mockup.py", line 57, in send_data
    sock.connect((MODBUS_IP, MODBUS_PORT))
ConnectionRefusedError: [Errno 111] Connection refused
2023-06-18 17:07:27,235 INFO PID 8025 Playing video file 3.mp4
2023-06-18 17:07:27,292 ERROR PID 8025 Exception occurred
Traceback (most recent call last):
  File "/home/ichiro/factory-mockup/mockup.py", line 57, in send_data
    sock.connect((MODBUS_IP, MODBUS_PORT))
ConnectionRefusedError: [Errno 111] Connection refused
2023-06-18 17:07:27,797 INFO PID 8025 Playing video file 4.mp4
2023-06-18 17:07:27,850 ERROR PID 8025 Exception occurred
Traceback (most recent call last):
  File "/home/ichiro/factory-mockup/mockup.py", line 57, in send_data
    sock.connect((MODBUS_IP, MODBUS_PORT))
ConnectionRefusedError: [Errno 111] Connection refused
2023-06-18 17:07:29,357 INFO PID 8025 Playing video file 2.mp4
2023-06-18 17:07:29,415 ERROR PID 8025 Exception occurred
Traceback (most recent call last):
  File "/home/ichiro/factory-mockup/mockup.py", line 57, in send_data
    sock.connect((MODBUS_IP, MODBUS_PORT))
ConnectionRefusedError: [Errno 111] Connection refused
2023-06-18 17:07:30,419 INFO PID 8025 Playing video file 5.mp4
2023-06-18 17:07:30,486 ERROR PID 8025 Exception occurred
Traceback (most recent call last):
  File "/home/ichiro/factory-mockup/mockup.py", line 57, in send_data
    sock.connect((MODBUS_IP, MODBUS_PORT))
ConnectionRefusedError: [Errno 111] Connection refused
2023-06-18 17:07:34,998 INFO PID 8025 Playing video file 2.mp4
2023-06-18 17:07:35,063 ERROR PID 8025 Exception occurred
Traceback (most recent call last):
  File "/home/ichiro/factory-mockup/mockup.py", line 57, in send_data
    sock.connect((MODBUS_IP, MODBUS_PORT))
ConnectionRefusedError: [Errno 111] Connection refused
2023-06-18 17:07:38,571 INFO PID 8025 Playing video file 4.mp4
2023-06-18 17:07:38,644 ERROR PID 8025 Exception occurred
Traceback (most recent call last):
  File "/home/ichiro/factory-mockup/mockup.py", line 57, in send_data
    sock.connect((MODBUS_IP, MODBUS_PORT))
ConnectionRefusedError: [Errno 111] Connection refused
2023-06-18 17:07:42,653 INFO PID 8025 Playing video file 5.mp4
2023-06-18 17:07:42,688 ERROR PID 8025 Exception occurred
Traceback (most recent call last):
  File "/home/ichiro/factory-mockup/mockup.py", line 57, in send_data
    sock.connect((MODBUS_IP, MODBUS_PORT))
ConnectionRefusedError: [Errno 111] Connection refused
2023-06-18 17:07:43,693 INFO PID 8025 Playing video file 5.mp4
2023-06-18 17:07:43,758 ERROR PID 8025 Exception occurred
Traceback (most recent call last):
  File "/home/ichiro/factory-mockup/mockup.py", line 57, in send_data
    sock.connect((MODBUS_IP, MODBUS_PORT))
ConnectionRefusedError: [Errno 111] Connection refused
2023-06-18 17:07:44,762 INFO PID 8025 Playing video file 4.mp4
2023-06-18 17:07:44,801 ERROR PID 8025 Exception occurred
Traceback (most recent call last):
  File "/home/ichiro/factory-mockup/mockup.py", line 57, in send_data
    sock.connect((MODBUS_IP, MODBUS_PORT))
ConnectionRefusedError: [Errno 111] Connection refused
2023-06-18 17:07:45,807 INFO PID 8025 Playing video file 1.mp4
2023-06-18 17:07:45,870 ERROR PID 8025 Exception occurred
Traceback (most recent call last):
  File "/home/ichiro/factory-mockup/mockup.py", line 57, in send_data
    sock.connect((MODBUS_IP, MODBUS_PORT))
ConnectionRefusedError: [Errno 111] Connection refused
2023-06-18 17:07:51,383 INFO PID 8025 Playing video file 5.mp4
2023-06-18 17:07:51,462 ERROR PID 8025 Exception occurred
Traceback (most recent call last):
  File "/home/ichiro/factory-mockup/mockup.py", line 57, in send_data
    sock.connect((MODBUS_IP, MODBUS_PORT))
ConnectionRefusedError: [Errno 111] Connection refused
2023-06-18 17:07:52,973 INFO PID 8025 Playing video file 5.mp4
2023-06-18 17:07:53,029 ERROR PID 8025 Exception occurred
Traceback (most recent call last):
  File "/home/ichiro/factory-mockup/mockup.py", line 57, in send_data
    sock.connect((MODBUS_IP, MODBUS_PORT))
ConnectionRefusedError: [Errno 111] Connection refused
2023-06-18 17:07:54,033 INFO PID 8025 Playing video file 1.mp4
2023-06-18 17:07:54,081 ERROR PID 8025 Exception occurred
Traceback (most recent call last):
  File "/home/ichiro/factory-mockup/mockup.py", line 57, in send_data
    sock.connect((MODBUS_IP, MODBUS_PORT))
ConnectionRefusedError: [Errno 111] Connection refused
2023-06-18 17:07:57,592 INFO PID 8025 Playing video file 4.mp4
2023-06-18 17:07:57,674 ERROR PID 8025 Exception occurred
Traceback (most recent call last):
  File "/home/ichiro/factory-mockup/mockup.py", line 57, in send_data
    sock.connect((MODBUS_IP, MODBUS_PORT))
ConnectionRefusedError: [Errno 111] Connection refused
2023-06-18 17:07:59,180 INFO PID 8025 Playing video file 3.mp4
2023-06-18 17:07:59,228 ERROR PID 8025 Exception occurred
Traceback (most recent call last):
  File "/home/ichiro/factory-mockup/mockup.py", line 57, in send_data
    sock.connect((MODBUS_IP, MODBUS_PORT))
ConnectionRefusedError: [Errno 111] Connection refused
2023-06-18 17:08:00,733 INFO PID 8025 Playing video file 4.mp4
2023-06-18 17:08:00,839 ERROR PID 8025 Exception occurred
Traceback (most recent call last):
  File "/home/ichiro/factory-mockup/mockup.py", line 57, in send_data
    sock.connect((MODBUS_IP, MODBUS_PORT))
ConnectionRefusedError: [Errno 111] Connection refused
2023-06-18 17:08:01,847 INFO PID 8025 Playing video file 3.mp4
2023-06-18 17:08:01,871 ERROR PID 8025 Exception occurred
Traceback (most recent call last):
  File "/home/ichiro/factory-mockup/mockup.py", line 57, in send_data
    sock.connect((MODBUS_IP, MODBUS_PORT))
ConnectionRefusedError: [Errno 111] Connection refused
2023-06-18 17:08:03,376 INFO PID 8025 Playing video file 4.mp4
2023-06-18 17:08:03,443 ERROR PID 8025 Exception occurred
Traceback (most recent call last):
  File "/home/ichiro/factory-mockup/mockup.py", line 57, in send_data
    sock.connect((MODBUS_IP, MODBUS_PORT))
ConnectionRefusedError: [Errno 111] Connection refused
2023-06-18 17:08:38,013 INFO PID 8221 Playing video file 5.mp4
2023-06-18 17:08:38,063 ERROR PID 8221 Exception occurred
Traceback (most recent call last):
  File "/home/ichiro/factory-mockup/mockup.py", line 57, in send_data
    sock.connect((MODBUS_IP, MODBUS_PORT))
ConnectionRefusedError: [Errno 111] Connection refused
2023-06-18 17:08:45,298 INFO PID 8221 Playing video file 1.mp4
2023-06-18 17:08:45,331 ERROR PID 8221 Exception occurred
Traceback (most recent call last):
  File "/home/ichiro/factory-mockup/mockup.py", line 57, in send_data
    sock.connect((MODBUS_IP, MODBUS_PORT))
ConnectionRefusedError: [Errno 111] Connection refused
2023-06-18 17:08:46,438 INFO PID 8221 Playing video file 2.mp4
2023-06-18 17:08:46,507 ERROR PID 8221 Exception occurred
Traceback (most recent call last):
  File "/home/ichiro/factory-mockup/mockup.py", line 57, in send_data
    sock.connect((MODBUS_IP, MODBUS_PORT))
ConnectionRefusedError: [Errno 111] Connection refused
2023-06-18 17:08:49,825 INFO PID 8221 Playing video file 5.mp4
2023-06-18 17:08:49,887 ERROR PID 8221 Exception occurred
Traceback (most recent call last):
  File "/home/ichiro/factory-mockup/mockup.py", line 57, in send_data
    sock.connect((MODBUS_IP, MODBUS_PORT))
ConnectionRefusedError: [Errno 111] Connection refused
2023-06-18 17:08:50,995 INFO PID 8221 Playing video file 5.mp4
2023-06-18 17:08:51,055 ERROR PID 8221 Exception occurred
Traceback (most recent call last):
  File "/home/ichiro/factory-mockup/mockup.py", line 57, in send_data
    sock.connect((MODBUS_IP, MODBUS_PORT))
ConnectionRefusedError: [Errno 111] Connection refused
2023-06-18 17:08:51,962 INFO PID 8221 Playing video file 3.mp4
2023-06-18 17:08:52,017 ERROR PID 8221 Exception occurred
Traceback (most recent call last):
  File "/home/ichiro/factory-mockup/mockup.py", line 57, in send_data
    sock.connect((MODBUS_IP, MODBUS_PORT))
ConnectionRefusedError: [Errno 111] Connection refused
2023-06-18 17:08:53,326 INFO PID 8221 Playing video file 3.mp4
2023-06-18 17:08:53,383 ERROR PID 8221 Exception occurred
Traceback (most recent call last):
  File "/home/ichiro/factory-mockup/mockup.py", line 57, in send_data
    sock.connect((MODBUS_IP, MODBUS_PORT))
ConnectionRefusedError: [Errno 111] Connection refused
2023-06-18 17:08:54,492 INFO PID 8221 Playing video file 2.mp4
2023-06-18 17:08:54,550 ERROR PID 8221 Exception occurred
Traceback (most recent call last):
  File "/home/ichiro/factory-mockup/mockup.py", line 57, in send_data
    sock.connect((MODBUS_IP, MODBUS_PORT))
ConnectionRefusedError: [Errno 111] Connection refused
2023-06-18 17:08:57,164 INFO PID 8221 Playing video file 3.mp4
2023-06-18 17:08:57,220 ERROR PID 8221 Exception occurred
Traceback (most recent call last):
  File "/home/ichiro/factory-mockup/mockup.py", line 57, in send_data
    sock.connect((MODBUS_IP, MODBUS_PORT))
ConnectionRefusedError: [Errno 111] Connection refused
2023-06-18 17:08:58,428 INFO PID 8221 Playing video file 3.mp4
2023-06-18 17:08:58,493 ERROR PID 8221 Exception occurred
Traceback (most recent call last):
  File "/home/ichiro/factory-mockup/mockup.py", line 57, in send_data
    sock.connect((MODBUS_IP, MODBUS_PORT))
ConnectionRefusedError: [Errno 111] Connection refused
2023-06-18 17:08:59,600 INFO PID 8221 Playing video file 1.mp4
2023-06-18 17:08:59,644 ERROR PID 8221 Exception occurred
Traceback (most recent call last):
  File "/home/ichiro/factory-mockup/mockup.py", line 57, in send_data
    sock.connect((MODBUS_IP, MODBUS_PORT))
ConnectionRefusedError: [Errno 111] Connection refused
2023-06-18 17:09:00,951 INFO PID 8221 Playing video file 4.mp4
2023-06-18 17:09:01,018 ERROR PID 8221 Exception occurred
Traceback (most recent call last):
  File "/home/ichiro/factory-mockup/mockup.py", line 57, in send_data
    sock.connect((MODBUS_IP, MODBUS_PORT))
ConnectionRefusedError: [Errno 111] Connection refused
2023-06-18 17:09:01,925 INFO PID 8221 Playing video file 3.mp4
2023-06-18 17:09:01,948 ERROR PID 8221 Exception occurred
Traceback (most recent call last):
  File "/home/ichiro/factory-mockup/mockup.py", line 57, in send_data
    sock.connect((MODBUS_IP, MODBUS_PORT))
ConnectionRefusedError: [Errno 111] Connection refused
2023-06-18 17:09:02,152 INFO PID 8221 Playing video file 4.mp4
2023-06-18 17:09:02,265 ERROR PID 8221 Exception occurred
Traceback (most recent call last):
  File "/home/ichiro/factory-mockup/mockup.py", line 57, in send_data
    sock.connect((MODBUS_IP, MODBUS_PORT))
ConnectionRefusedError: [Errno 111] Connection refused
2023-06-18 17:09:02,617 INFO PID 8221 Playing video file 3.mp4
2023-06-18 17:09:02,691 ERROR PID 8221 Exception occurred
Traceback (most recent call last):
  File "/home/ichiro/factory-mockup/mockup.py", line 57, in send_data
    sock.connect((MODBUS_IP, MODBUS_PORT))
ConnectionRefusedError: [Errno 111] Connection refused
2023-06-18 17:09:03,399 INFO PID 8221 Playing video file 3.mp4
2023-06-18 17:09:03,432 ERROR PID 8221 Exception occurred
Traceback (most recent call last):
  File "/home/ichiro/factory-mockup/mockup.py", line 57, in send_data
    sock.connect((MODBUS_IP, MODBUS_PORT))
ConnectionRefusedError: [Errno 111] Connection refused
2023-06-18 17:09:04,138 INFO PID 8221 Playing video file 3.mp4
2023-06-18 17:09:04,177 ERROR PID 8221 Exception occurred
Traceback (most recent call last):
  File "/home/ichiro/factory-mockup/mockup.py", line 57, in send_data
    sock.connect((MODBUS_IP, MODBUS_PORT))
ConnectionRefusedError: [Errno 111] Connection refused
2023-06-18 17:09:04,884 INFO PID 8221 Playing video file 1.mp4
2023-06-18 17:09:04,946 ERROR PID 8221 Exception occurred
Traceback (most recent call last):
  File "/home/ichiro/factory-mockup/mockup.py", line 57, in send_data
    sock.connect((MODBUS_IP, MODBUS_PORT))
ConnectionRefusedError: [Errno 111] Connection refused
2023-06-18 17:09:06,557 INFO PID 8221 Playing video file 5.mp4
2023-06-18 17:09:06,620 ERROR PID 8221 Exception occurred
Traceback (most recent call last):
  File "/home/ichiro/factory-mockup/mockup.py", line 57, in send_data
    sock.connect((MODBUS_IP, MODBUS_PORT))
ConnectionRefusedError: [Errno 111] Connection refused
2023-06-18 17:09:07,328 INFO PID 8221 Playing video file 4.mp4
2023-06-18 17:09:07,385 ERROR PID 8221 Exception occurred
Traceback (most recent call last):
  File "/home/ichiro/factory-mockup/mockup.py", line 57, in send_data
    sock.connect((MODBUS_IP, MODBUS_PORT))
ConnectionRefusedError: [Errno 111] Connection refused
2023-06-18 17:09:08,091 INFO PID 8221 Playing video file 2.mp4
2023-06-18 17:09:08,148 ERROR PID 8221 Exception occurred
Traceback (most recent call last):
  File "/home/ichiro/factory-mockup/mockup.py", line 57, in send_data
    sock.connect((MODBUS_IP, MODBUS_PORT))
ConnectionRefusedError: [Errno 111] Connection refused
2023-06-18 17:09:08,855 INFO PID 8221 Playing video file 5.mp4
2023-06-18 17:09:08,919 ERROR PID 8221 Exception occurred
Traceback (most recent call last):
  File "/home/ichiro/factory-mockup/mockup.py", line 57, in send_data
    sock.connect((MODBUS_IP, MODBUS_PORT))
ConnectionRefusedError: [Errno 111] Connection refused
2023-06-18 17:09:09,626 INFO PID 8221 Playing video file 3.mp4
2023-06-18 17:09:09,688 ERROR PID 8221 Exception occurred
Traceback (most recent call last):
  File "/home/ichiro/factory-mockup/mockup.py", line 57, in send_data
    sock.connect((MODBUS_IP, MODBUS_PORT))
ConnectionRefusedError: [Errno 111] Connection refused
2023-06-18 17:09:12,405 INFO PID 8221 Playing video file 1.mp4
2023-06-18 17:09:12,432 ERROR PID 8221 Exception occurred
Traceback (most recent call last):
  File "/home/ichiro/factory-mockup/mockup.py", line 57, in send_data
    sock.connect((MODBUS_IP, MODBUS_PORT))
ConnectionRefusedError: [Errno 111] Connection refused
2023-06-18 17:09:14,140 INFO PID 8221 Playing video file 5.mp4
2023-06-18 17:09:14,209 ERROR PID 8221 Exception occurred
Traceback (most recent call last):
  File "/home/ichiro/factory-mockup/mockup.py", line 57, in send_data
    sock.connect((MODBUS_IP, MODBUS_PORT))
ConnectionRefusedError: [Errno 111] Connection refused
2023-06-18 17:09:15,215 INFO PID 8221 Playing video file 1.mp4
2023-06-18 17:09:15,249 ERROR PID 8221 Exception occurred
Traceback (most recent call last):
  File "/home/ichiro/factory-mockup/mockup.py", line 57, in send_data
    sock.connect((MODBUS_IP, MODBUS_PORT))
ConnectionRefusedError: [Errno 111] Connection refused
2023-06-18 17:09:16,155 INFO PID 8221 Playing video file 5.mp4
2023-06-18 17:09:16,224 ERROR PID 8221 Exception occurred
Traceback (most recent call last):
  File "/home/ichiro/factory-mockup/mockup.py", line 57, in send_data
    sock.connect((MODBUS_IP, MODBUS_PORT))
ConnectionRefusedError: [Errno 111] Connection refused
2023-06-18 17:09:17,133 INFO PID 8221 Playing video file 5.mp4
2023-06-18 17:09:17,163 ERROR PID 8221 Exception occurred
Traceback (most recent call last):
  File "/home/ichiro/factory-mockup/mockup.py", line 57, in send_data
    sock.connect((MODBUS_IP, MODBUS_PORT))
ConnectionRefusedError: [Errno 111] Connection refused
2023-06-18 17:09:18,772 INFO PID 8221 Playing video file 5.mp4
2023-06-18 17:09:18,864 ERROR PID 8221 Exception occurred
Traceback (most recent call last):
  File "/home/ichiro/factory-mockup/mockup.py", line 57, in send_data
    sock.connect((MODBUS_IP, MODBUS_PORT))
ConnectionRefusedError: [Errno 111] Connection refused
2023-06-18 17:09:19,573 INFO PID 8221 Playing video file 1.mp4
2023-06-18 17:09:19,618 ERROR PID 8221 Exception occurred
Traceback (most recent call last):
  File "/home/ichiro/factory-mockup/mockup.py", line 57, in send_data
    sock.connect((MODBUS_IP, MODBUS_PORT))
ConnectionRefusedError: [Errno 111] Connection refused
2023-06-18 17:09:20,427 INFO PID 8221 Playing video file 5.mp4
2023-06-18 17:09:20,489 ERROR PID 8221 Exception occurred
Traceback (most recent call last):
  File "/home/ichiro/factory-mockup/mockup.py", line 57, in send_data
    sock.connect((MODBUS_IP, MODBUS_PORT))
ConnectionRefusedError: [Errno 111] Connection refused
2023-06-18 17:09:23,008 INFO PID 8221 Playing video file 1.mp4
2023-06-18 17:09:23,074 ERROR PID 8221 Exception occurred
Traceback (most recent call last):
  File "/home/ichiro/factory-mockup/mockup.py", line 57, in send_data
    sock.connect((MODBUS_IP, MODBUS_PORT))
ConnectionRefusedError: [Errno 111] Connection refused
2023-06-18 17:09:23,981 INFO PID 8221 Playing video file 5.mp4
2023-06-18 17:09:24,040 ERROR PID 8221 Exception occurred
Traceback (most recent call last):
  File "/home/ichiro/factory-mockup/mockup.py", line 57, in send_data
    sock.connect((MODBUS_IP, MODBUS_PORT))
ConnectionRefusedError: [Errno 111] Connection refused
2023-06-18 17:09:24,848 INFO PID 8221 Playing video file 4.mp4
2023-06-18 17:09:24,911 ERROR PID 8221 Exception occurred
Traceback (most recent call last):
  File "/home/ichiro/factory-mockup/mockup.py", line 57, in send_data
    sock.connect((MODBUS_IP, MODBUS_PORT))
ConnectionRefusedError: [Errno 111] Connection refused
2023-06-18 17:24:37,912 INFO PID 8666 Start player
2023-06-18 17:25:23,922 INFO PID 8666 Playing video file 4.mp4
2023-06-18 17:25:24,063 ERROR PID 8666 Exception occurred
Traceback (most recent call last):
  File "/home/ichiro/factory-mockup/mockup.py", line 57, in send_data
    sock.connect((MODBUS_IP, MODBUS_PORT))
ConnectionRefusedError: [Errno 111] Connection refused
2023-06-18 17:25:29,620 INFO PID 8666 Playing video file 3.mp4
2023-06-18 17:25:29,744 ERROR PID 8666 Exception occurred
Traceback (most recent call last):
  File "/home/ichiro/factory-mockup/mockup.py", line 57, in send_data
    sock.connect((MODBUS_IP, MODBUS_PORT))
ConnectionRefusedError: [Errno 111] Connection refused
2023-06-18 17:25:31,391 INFO PID 8666 Playing video file 4.mp4
2023-06-18 17:25:31,513 ERROR PID 8666 Exception occurred
Traceback (most recent call last):
  File "/home/ichiro/factory-mockup/mockup.py", line 57, in send_data
    sock.connect((MODBUS_IP, MODBUS_PORT))
ConnectionRefusedError: [Errno 111] Connection refused
2023-06-18 17:25:33,168 INFO PID 8666 Playing video file 3.mp4
2023-06-18 17:25:33,267 ERROR PID 8666 Exception occurred
Traceback (most recent call last):
  File "/home/ichiro/factory-mockup/mockup.py", line 57, in send_data
    sock.connect((MODBUS_IP, MODBUS_PORT))
ConnectionRefusedError: [Errno 111] Connection refused
2023-06-18 17:25:33,383 INFO PID 8666 Playing video file 3.mp4
2023-06-18 17:25:33,646 ERROR PID 8666 Exception occurred
Traceback (most recent call last):
  File "/home/ichiro/factory-mockup/mockup.py", line 57, in send_data
    sock.connect((MODBUS_IP, MODBUS_PORT))
ConnectionRefusedError: [Errno 111] Connection refused
2023-06-18 17:25:34,863 INFO PID 8666 Playing video file 2.mp4
2023-06-18 17:25:34,973 ERROR PID 8666 Exception occurred
Traceback (most recent call last):
  File "/home/ichiro/factory-mockup/mockup.py", line 57, in send_data
    sock.connect((MODBUS_IP, MODBUS_PORT))
ConnectionRefusedError: [Errno 111] Connection refused
2023-06-18 17:25:37,799 INFO PID 8666 Playing video file 3.mp4
2023-06-18 17:25:37,985 ERROR PID 8666 Exception occurred
Traceback (most recent call last):
  File "/home/ichiro/factory-mockup/mockup.py", line 57, in send_data
    sock.connect((MODBUS_IP, MODBUS_PORT))
ConnectionRefusedError: [Errno 111] Connection refused
2023-06-18 17:25:39,404 INFO PID 8666 Playing video file 1.mp4
2023-06-18 17:25:39,561 ERROR PID 8666 Exception occurred
Traceback (most recent call last):
  File "/home/ichiro/factory-mockup/mockup.py", line 57, in send_data
    sock.connect((MODBUS_IP, MODBUS_PORT))
ConnectionRefusedError: [Errno 111] Connection refused
2023-06-18 17:25:40,980 INFO PID 8666 Playing video file 1.mp4
2023-06-18 17:25:41,129 ERROR PID 8666 Exception occurred
Traceback (most recent call last):
  File "/home/ichiro/factory-mockup/mockup.py", line 57, in send_data
    sock.connect((MODBUS_IP, MODBUS_PORT))
ConnectionRefusedError: [Errno 111] Connection refused
2023-06-18 17:25:42,349 INFO PID 8666 Playing video file 4.mp4
2023-06-18 17:25:42,429 ERROR PID 8666 Exception occurred
Traceback (most recent call last):
  File "/home/ichiro/factory-mockup/mockup.py", line 57, in send_data
    sock.connect((MODBUS_IP, MODBUS_PORT))
ConnectionRefusedError: [Errno 111] Connection refused
2023-06-18 17:37:14,581 INFO PID 8666 Playing video file 4.mp4
2023-06-18 17:37:14,771 ERROR PID 8666 Exception occurred
Traceback (most recent call last):
  File "/home/ichiro/factory-mockup/mockup.py", line 57, in send_data
    sock.connect((MODBUS_IP, MODBUS_PORT))
ConnectionRefusedError: [Errno 111] Connection refused
2023-06-18 17:40:13,724 INFO PID 12245 Start player
2023-06-18 17:41:28,932 INFO PID 12245 Playing video file 4.mp4
2023-06-18 17:41:29,036 ERROR PID 12245 Exception occurred
Traceback (most recent call last):
  File "/home/ichiro/factory-mockup/mockup.py", line 58, in send_data
    sock.connect((MODBUS_IP, MODBUS_PORT))
ConnectionRefusedError: [Errno 111] Connection refused
2023-06-18 17:41:32,262 INFO PID 12245 Playing video file 1.mp4
2023-06-18 17:41:32,346 ERROR PID 12245 Exception occurred
Traceback (most recent call last):
  File "/home/ichiro/factory-mockup/mockup.py", line 58, in send_data
    sock.connect((MODBUS_IP, MODBUS_PORT))
ConnectionRefusedError: [Errno 111] Connection refused
2023-06-18 17:41:38,498 INFO PID 12245 Playing video file 5.mp4
2023-06-18 17:41:38,623 ERROR PID 12245 Exception occurred
Traceback (most recent call last):
  File "/home/ichiro/factory-mockup/mockup.py", line 58, in send_data
    sock.connect((MODBUS_IP, MODBUS_PORT))
ConnectionRefusedError: [Errno 111] Connection refused
2023-06-18 17:41:44,064 INFO PID 12245 Playing video file 5.mp4
2023-06-18 17:41:44,169 ERROR PID 12245 Exception occurred
Traceback (most recent call last):
  File "/home/ichiro/factory-mockup/mockup.py", line 58, in send_data
    sock.connect((MODBUS_IP, MODBUS_PORT))
ConnectionRefusedError: [Errno 111] Connection refused
2023-06-18 17:41:45,484 INFO PID 12245 Playing video file 4.mp4
2023-06-18 17:41:45,581 ERROR PID 12245 Exception occurred
Traceback (most recent call last):
  File "/home/ichiro/factory-mockup/mockup.py", line 58, in send_data
    sock.connect((MODBUS_IP, MODBUS_PORT))
ConnectionRefusedError: [Errno 111] Connection refused
2023-06-18 17:41:47,907 INFO PID 12245 Playing video file 5.mp4
2023-06-18 17:41:48,132 ERROR PID 12245 Exception occurred
Traceback (most recent call last):
  File "/home/ichiro/factory-mockup/mockup.py", line 58, in send_data
    sock.connect((MODBUS_IP, MODBUS_PORT))
ConnectionRefusedError: [Errno 111] Connection refused
2023-06-18 17:41:50,880 INFO PID 12245 Playing video file 5.mp4
2023-06-18 17:41:50,948 ERROR PID 12245 Exception occurred
Traceback (most recent call last):
  File "/home/ichiro/factory-mockup/mockup.py", line 58, in send_data
    sock.connect((MODBUS_IP, MODBUS_PORT))
ConnectionRefusedError: [Errno 111] Connection refused
2023-06-18 17:41:55,483 INFO PID 12245 Playing video file 2.mp4
2023-06-18 17:41:55,554 ERROR PID 12245 Exception occurred
Traceback (most recent call last):
  File "/home/ichiro/factory-mockup/mockup.py", line 58, in send_data
    sock.connect((MODBUS_IP, MODBUS_PORT))
ConnectionRefusedError: [Errno 111] Connection refused
2023-06-18 17:41:56,572 INFO PID 12245 Playing video file 2.mp4
2023-06-18 17:41:56,644 ERROR PID 12245 Exception occurred
Traceback (most recent call last):
  File "/home/ichiro/factory-mockup/mockup.py", line 58, in send_data
    sock.connect((MODBUS_IP, MODBUS_PORT))
ConnectionRefusedError: [Errno 111] Connection refused
2023-06-18 17:41:57,351 INFO PID 12245 Playing video file 2.mp4
2023-06-18 17:41:57,413 ERROR PID 12245 Exception occurred
Traceback (most recent call last):
  File "/home/ichiro/factory-mockup/mockup.py", line 58, in send_data
    sock.connect((MODBUS_IP, MODBUS_PORT))
ConnectionRefusedError: [Errno 111] Connection refused
2023-06-18 17:41:58,223 INFO PID 12245 Playing video file 2.mp4
2023-06-18 17:41:58,293 ERROR PID 12245 Exception occurred
Traceback (most recent call last):
  File "/home/ichiro/factory-mockup/mockup.py", line 58, in send_data
    sock.connect((MODBUS_IP, MODBUS_PORT))
ConnectionRefusedError: [Errno 111] Connection refused
2023-06-18 17:42:00,911 INFO PID 12245 Playing video file 1.mp4
2023-06-18 17:42:00,984 ERROR PID 12245 Exception occurred
Traceback (most recent call last):
  File "/home/ichiro/factory-mockup/mockup.py", line 58, in send_data
    sock.connect((MODBUS_IP, MODBUS_PORT))
ConnectionRefusedError: [Errno 111] Connection refused
2023-06-18 17:42:02,098 INFO PID 12245 Playing video file 3.mp4
2023-06-18 17:42:02,209 ERROR PID 12245 Exception occurred
Traceback (most recent call last):
  File "/home/ichiro/factory-mockup/mockup.py", line 58, in send_data
    sock.connect((MODBUS_IP, MODBUS_PORT))
ConnectionRefusedError: [Errno 111] Connection refused
2023-06-18 17:42:03,120 INFO PID 12245 Playing video file 1.mp4
2023-06-18 17:42:03,200 ERROR PID 12245 Exception occurred
Traceback (most recent call last):
  File "/home/ichiro/factory-mockup/mockup.py", line 58, in send_data
    sock.connect((MODBUS_IP, MODBUS_PORT))
ConnectionRefusedError: [Errno 111] Connection refused
2023-06-18 17:42:03,914 INFO PID 12245 Playing video file 5.mp4
2023-06-18 17:42:03,995 ERROR PID 12245 Exception occurred
Traceback (most recent call last):
  File "/home/ichiro/factory-mockup/mockup.py", line 58, in send_data
    sock.connect((MODBUS_IP, MODBUS_PORT))
ConnectionRefusedError: [Errno 111] Connection refused
2023-06-18 17:42:04,706 INFO PID 12245 Playing video file 2.mp4
2023-06-18 17:42:04,779 ERROR PID 12245 Exception occurred
Traceback (most recent call last):
  File "/home/ichiro/factory-mockup/mockup.py", line 58, in send_data
    sock.connect((MODBUS_IP, MODBUS_PORT))
ConnectionRefusedError: [Errno 111] Connection refused
2023-06-18 17:42:06,195 INFO PID 12245 Playing video file 5.mp4
2023-06-18 17:42:06,265 ERROR PID 12245 Exception occurred
Traceback (most recent call last):
  File "/home/ichiro/factory-mockup/mockup.py", line 58, in send_data
    sock.connect((MODBUS_IP, MODBUS_PORT))
ConnectionRefusedError: [Errno 111] Connection refused
2023-06-18 17:42:12,814 INFO PID 12245 Playing video file 5.mp4
2023-06-18 17:42:12,935 ERROR PID 12245 Exception occurred
Traceback (most recent call last):
  File "/home/ichiro/factory-mockup/mockup.py", line 58, in send_data
    sock.connect((MODBUS_IP, MODBUS_PORT))
ConnectionRefusedError: [Errno 111] Connection refused
2023-06-18 17:42:14,348 INFO PID 12245 Playing video file 3.mp4
2023-06-18 17:42:14,428 ERROR PID 12245 Exception occurred
Traceback (most recent call last):
  File "/home/ichiro/factory-mockup/mockup.py", line 58, in send_data
    sock.connect((MODBUS_IP, MODBUS_PORT))
ConnectionRefusedError: [Errno 111] Connection refused
2023-06-18 17:42:16,245 INFO PID 12245 Playing video file 5.mp4
2023-06-18 17:42:16,321 ERROR PID 12245 Exception occurred
Traceback (most recent call last):
  File "/home/ichiro/factory-mockup/mockup.py", line 58, in send_data
    sock.connect((MODBUS_IP, MODBUS_PORT))
ConnectionRefusedError: [Errno 111] Connection refused
2023-06-18 17:42:17,338 INFO PID 12245 Playing video file 2.mp4
2023-06-18 17:42:17,414 ERROR PID 12245 Exception occurred
Traceback (most recent call last):
  File "/home/ichiro/factory-mockup/mockup.py", line 58, in send_data
    sock.connect((MODBUS_IP, MODBUS_PORT))
ConnectionRefusedError: [Errno 111] Connection refused
2023-06-18 17:42:18,223 INFO PID 12245 Playing video file 5.mp4
2023-06-18 17:42:18,297 ERROR PID 12245 Exception occurred
Traceback (most recent call last):
  File "/home/ichiro/factory-mockup/mockup.py", line 58, in send_data
    sock.connect((MODBUS_IP, MODBUS_PORT))
ConnectionRefusedError: [Errno 111] Connection refused
2023-06-18 17:42:19,911 INFO PID 12245 Playing video file 5.mp4
2023-06-18 17:42:19,990 ERROR PID 12245 Exception occurred
Traceback (most recent call last):
  File "/home/ichiro/factory-mockup/mockup.py", line 58, in send_data
    sock.connect((MODBUS_IP, MODBUS_PORT))
ConnectionRefusedError: [Errno 111] Connection refused
2023-06-18 17:42:20,799 INFO PID 12245 Playing video file 4.mp4
2023-06-18 17:42:20,863 ERROR PID 12245 Exception occurred
Traceback (most recent call last):
  File "/home/ichiro/factory-mockup/mockup.py", line 58, in send_data
    sock.connect((MODBUS_IP, MODBUS_PORT))
ConnectionRefusedError: [Errno 111] Connection refused
2023-06-18 17:42:21,772 INFO PID 12245 Playing video file 4.mp4
2023-06-18 17:42:21,873 ERROR PID 12245 Exception occurred
Traceback (most recent call last):
  File "/home/ichiro/factory-mockup/mockup.py", line 58, in send_data
    sock.connect((MODBUS_IP, MODBUS_PORT))
ConnectionRefusedError: [Errno 111] Connection refused
2023-06-18 17:42:22,789 INFO PID 12245 Playing video file 3.mp4
2023-06-18 17:42:22,890 ERROR PID 12245 Exception occurred
Traceback (most recent call last):
  File "/home/ichiro/factory-mockup/mockup.py", line 58, in send_data
    sock.connect((MODBUS_IP, MODBUS_PORT))
ConnectionRefusedError: [Errno 111] Connection refused
2023-06-18 17:42:23,701 INFO PID 12245 Playing video file 3.mp4
2023-06-18 17:42:23,780 ERROR PID 12245 Exception occurred
Traceback (most recent call last):
  File "/home/ichiro/factory-mockup/mockup.py", line 58, in send_data
    sock.connect((MODBUS_IP, MODBUS_PORT))
ConnectionRefusedError: [Errno 111] Connection refused
2023-06-18 17:42:24,591 INFO PID 12245 Playing video file 2.mp4
2023-06-18 17:42:24,670 ERROR PID 12245 Exception occurred
Traceback (most recent call last):
  File "/home/ichiro/factory-mockup/mockup.py", line 58, in send_data
    sock.connect((MODBUS_IP, MODBUS_PORT))
ConnectionRefusedError: [Errno 111] Connection refused
2023-06-18 17:42:28,698 INFO PID 12245 Playing video file 2.mp4
2023-06-18 17:42:28,776 ERROR PID 12245 Exception occurred
Traceback (most recent call last):
  File "/home/ichiro/factory-mockup/mockup.py", line 58, in send_data
    sock.connect((MODBUS_IP, MODBUS_PORT))
ConnectionRefusedError: [Errno 111] Connection refused
2023-06-18 17:42:30,592 INFO PID 12245 Playing video file 2.mp4
2023-06-18 17:42:30,669 ERROR PID 12245 Exception occurred
Traceback (most recent call last):
  File "/home/ichiro/factory-mockup/mockup.py", line 58, in send_data
    sock.connect((MODBUS_IP, MODBUS_PORT))
ConnectionRefusedError: [Errno 111] Connection refused
2023-06-18 17:42:35,902 INFO PID 12245 Playing video file 1.mp4
2023-06-18 17:42:35,998 ERROR PID 12245 Exception occurred
Traceback (most recent call last):
  File "/home/ichiro/factory-mockup/mockup.py", line 58, in send_data
    sock.connect((MODBUS_IP, MODBUS_PORT))
ConnectionRefusedError: [Errno 111] Connection refused
2023-06-18 17:42:36,814 INFO PID 12245 Playing video file 5.mp4
2023-06-18 17:42:36,890 ERROR PID 12245 Exception occurred
Traceback (most recent call last):
  File "/home/ichiro/factory-mockup/mockup.py", line 58, in send_data
    sock.connect((MODBUS_IP, MODBUS_PORT))
ConnectionRefusedError: [Errno 111] Connection refused
2023-06-18 17:42:37,802 INFO PID 12245 Playing video file 1.mp4
2023-06-18 17:42:37,932 ERROR PID 12245 Exception occurred
Traceback (most recent call last):
  File "/home/ichiro/factory-mockup/mockup.py", line 58, in send_data
    sock.connect((MODBUS_IP, MODBUS_PORT))
ConnectionRefusedError: [Errno 111] Connection refused
2023-06-18 17:42:38,751 INFO PID 12245 Playing video file 1.mp4
2023-06-18 17:42:38,848 ERROR PID 12245 Exception occurred
Traceback (most recent call last):
  File "/home/ichiro/factory-mockup/mockup.py", line 58, in send_data
    sock.connect((MODBUS_IP, MODBUS_PORT))
ConnectionRefusedError: [Errno 111] Connection refused
2023-06-18 17:42:39,563 INFO PID 12245 Playing video file 2.mp4
2023-06-18 17:42:39,641 ERROR PID 12245 Exception occurred
Traceback (most recent call last):
  File "/home/ichiro/factory-mockup/mockup.py", line 58, in send_data
    sock.connect((MODBUS_IP, MODBUS_PORT))
ConnectionRefusedError: [Errno 111] Connection refused
2023-06-18 17:42:40,754 INFO PID 12245 Playing video file 5.mp4
2023-06-18 17:42:40,824 ERROR PID 12245 Exception occurred
Traceback (most recent call last):
  File "/home/ichiro/factory-mockup/mockup.py", line 58, in send_data
    sock.connect((MODBUS_IP, MODBUS_PORT))
ConnectionRefusedError: [Errno 111] Connection refused
2023-06-18 17:42:41,634 INFO PID 12245 Playing video file 5.mp4
2023-06-18 17:42:41,709 ERROR PID 12245 Exception occurred
Traceback (most recent call last):
  File "/home/ichiro/factory-mockup/mockup.py", line 58, in send_data
    sock.connect((MODBUS_IP, MODBUS_PORT))
ConnectionRefusedError: [Errno 111] Connection refused
2023-06-18 17:42:42,420 INFO PID 12245 Playing video file 5.mp4
2023-06-18 17:42:42,504 ERROR PID 12245 Exception occurred
Traceback (most recent call last):
  File "/home/ichiro/factory-mockup/mockup.py", line 58, in send_data
    sock.connect((MODBUS_IP, MODBUS_PORT))
ConnectionRefusedError: [Errno 111] Connection refused
2023-06-18 17:42:43,222 INFO PID 12245 Playing video file 3.mp4
2023-06-18 17:42:43,311 ERROR PID 12245 Exception occurred
Traceback (most recent call last):
  File "/home/ichiro/factory-mockup/mockup.py", line 58, in send_data
    sock.connect((MODBUS_IP, MODBUS_PORT))
ConnectionRefusedError: [Errno 111] Connection refused
2023-06-18 17:42:44,022 INFO PID 12245 Playing video file 4.mp4
2023-06-18 17:42:44,089 ERROR PID 12245 Exception occurred
Traceback (most recent call last):
  File "/home/ichiro/factory-mockup/mockup.py", line 58, in send_data
    sock.connect((MODBUS_IP, MODBUS_PORT))
ConnectionRefusedError: [Errno 111] Connection refused
2023-06-18 17:42:44,903 INFO PID 12245 Playing video file 2.mp4
2023-06-18 17:42:44,981 ERROR PID 12245 Exception occurred
Traceback (most recent call last):
  File "/home/ichiro/factory-mockup/mockup.py", line 58, in send_data
    sock.connect((MODBUS_IP, MODBUS_PORT))
ConnectionRefusedError: [Errno 111] Connection refused
2023-06-18 17:42:45,692 INFO PID 12245 Playing video file 1.mp4
2023-06-18 17:42:45,757 ERROR PID 12245 Exception occurred
Traceback (most recent call last):
  File "/home/ichiro/factory-mockup/mockup.py", line 58, in send_data
    sock.connect((MODBUS_IP, MODBUS_PORT))
ConnectionRefusedError: [Errno 111] Connection refused
2023-06-18 17:42:46,569 INFO PID 12245 Playing video file 1.mp4
2023-06-18 17:42:46,663 ERROR PID 12245 Exception occurred
Traceback (most recent call last):
  File "/home/ichiro/factory-mockup/mockup.py", line 58, in send_data
    sock.connect((MODBUS_IP, MODBUS_PORT))
ConnectionRefusedError: [Errno 111] Connection refused
2023-06-18 17:42:47,479 INFO PID 12245 Playing video file 5.mp4
2023-06-18 17:42:47,557 ERROR PID 12245 Exception occurred
Traceback (most recent call last):
  File "/home/ichiro/factory-mockup/mockup.py", line 58, in send_data
    sock.connect((MODBUS_IP, MODBUS_PORT))
ConnectionRefusedError: [Errno 111] Connection refused
2023-06-18 17:42:48,367 INFO PID 12245 Playing video file 1.mp4
2023-06-18 17:42:48,438 ERROR PID 12245 Exception occurred
Traceback (most recent call last):
  File "/home/ichiro/factory-mockup/mockup.py", line 58, in send_data
    sock.connect((MODBUS_IP, MODBUS_PORT))
ConnectionRefusedError: [Errno 111] Connection refused
2023-06-18 17:42:49,147 INFO PID 12245 Playing video file 4.mp4
2023-06-18 17:42:49,227 ERROR PID 12245 Exception occurred
Traceback (most recent call last):
  File "/home/ichiro/factory-mockup/mockup.py", line 58, in send_data
    sock.connect((MODBUS_IP, MODBUS_PORT))
ConnectionRefusedError: [Errno 111] Connection refused
2023-06-18 17:42:50,044 INFO PID 12245 Playing video file 4.mp4
2023-06-18 17:42:50,124 ERROR PID 12245 Exception occurred
Traceback (most recent call last):
  File "/home/ichiro/factory-mockup/mockup.py", line 58, in send_data
    sock.connect((MODBUS_IP, MODBUS_PORT))
ConnectionRefusedError: [Errno 111] Connection refused
2023-06-18 17:42:51,939 INFO PID 12245 Playing video file 4.mp4
2023-06-18 17:42:52,017 ERROR PID 12245 Exception occurred
Traceback (most recent call last):
  File "/home/ichiro/factory-mockup/mockup.py", line 58, in send_data
    sock.connect((MODBUS_IP, MODBUS_PORT))
ConnectionRefusedError: [Errno 111] Connection refused
2023-06-18 17:42:52,123 INFO PID 12245 Playing video file 4.mp4
2023-06-18 17:42:52,276 ERROR PID 12245 Exception occurred
Traceback (most recent call last):
  File "/home/ichiro/factory-mockup/mockup.py", line 58, in send_data
    sock.connect((MODBUS_IP, MODBUS_PORT))
ConnectionRefusedError: [Errno 111] Connection refused
2023-06-18 17:42:52,983 INFO PID 12245 Playing video file 1.mp4
2023-06-18 17:42:53,049 ERROR PID 12245 Exception occurred
Traceback (most recent call last):
  File "/home/ichiro/factory-mockup/mockup.py", line 58, in send_data
    sock.connect((MODBUS_IP, MODBUS_PORT))
ConnectionRefusedError: [Errno 111] Connection refused
2023-06-18 17:42:54,663 INFO PID 12245 Playing video file 2.mp4
2023-06-18 17:42:54,750 ERROR PID 12245 Exception occurred
Traceback (most recent call last):
  File "/home/ichiro/factory-mockup/mockup.py", line 58, in send_data
    sock.connect((MODBUS_IP, MODBUS_PORT))
ConnectionRefusedError: [Errno 111] Connection refused
2023-06-18 17:42:54,858 INFO PID 12245 Playing video file 4.mp4
2023-06-18 17:42:55,000 ERROR PID 12245 Exception occurred
Traceback (most recent call last):
  File "/home/ichiro/factory-mockup/mockup.py", line 58, in send_data
    sock.connect((MODBUS_IP, MODBUS_PORT))
ConnectionRefusedError: [Errno 111] Connection refused
2023-06-18 17:42:55,910 INFO PID 12245 Playing video file 5.mp4
2023-06-18 17:42:55,979 ERROR PID 12245 Exception occurred
Traceback (most recent call last):
  File "/home/ichiro/factory-mockup/mockup.py", line 58, in send_data
    sock.connect((MODBUS_IP, MODBUS_PORT))
ConnectionRefusedError: [Errno 111] Connection refused
2023-06-18 17:42:56,084 INFO PID 12245 Playing video file 4.mp4
2023-06-18 17:42:56,255 ERROR PID 12245 Exception occurred
Traceback (most recent call last):
  File "/home/ichiro/factory-mockup/mockup.py", line 58, in send_data
    sock.connect((MODBUS_IP, MODBUS_PORT))
ConnectionRefusedError: [Errno 111] Connection refused
2023-06-18 17:42:57,066 INFO PID 12245 Playing video file 2.mp4
2023-06-18 17:42:57,156 ERROR PID 12245 Exception occurred
Traceback (most recent call last):
  File "/home/ichiro/factory-mockup/mockup.py", line 58, in send_data
    sock.connect((MODBUS_IP, MODBUS_PORT))
ConnectionRefusedError: [Errno 111] Connection refused
2023-06-18 17:42:57,967 INFO PID 12245 Playing video file 2.mp4
2023-06-18 17:42:58,042 ERROR PID 12245 Exception occurred
Traceback (most recent call last):
  File "/home/ichiro/factory-mockup/mockup.py", line 58, in send_data
    sock.connect((MODBUS_IP, MODBUS_PORT))
ConnectionRefusedError: [Errno 111] Connection refused
2023-06-18 17:42:59,053 INFO PID 12245 Playing video file 1.mp4
2023-06-18 17:42:59,121 ERROR PID 12245 Exception occurred
Traceback (most recent call last):
  File "/home/ichiro/factory-mockup/mockup.py", line 58, in send_data
    sock.connect((MODBUS_IP, MODBUS_PORT))
ConnectionRefusedError: [Errno 111] Connection refused
2023-06-18 17:43:00,230 INFO PID 12245 Playing video file 1.mp4
2023-06-18 17:43:00,342 ERROR PID 12245 Exception occurred
Traceback (most recent call last):
  File "/home/ichiro/factory-mockup/mockup.py", line 58, in send_data
    sock.connect((MODBUS_IP, MODBUS_PORT))
ConnectionRefusedError: [Errno 111] Connection refused
2023-06-18 17:43:04,381 INFO PID 12245 Playing video file 3.mp4
2023-06-18 17:43:04,464 ERROR PID 12245 Exception occurred
Traceback (most recent call last):
  File "/home/ichiro/factory-mockup/mockup.py", line 58, in send_data
    sock.connect((MODBUS_IP, MODBUS_PORT))
ConnectionRefusedError: [Errno 111] Connection refused
2023-06-18 17:43:05,885 INFO PID 12245 Playing video file 3.mp4
2023-06-18 17:43:05,955 ERROR PID 12245 Exception occurred
Traceback (most recent call last):
  File "/home/ichiro/factory-mockup/mockup.py", line 58, in send_data
    sock.connect((MODBUS_IP, MODBUS_PORT))
ConnectionRefusedError: [Errno 111] Connection refused
2023-06-18 17:43:06,872 INFO PID 12245 Playing video file 1.mp4
2023-06-18 17:43:06,946 ERROR PID 12245 Exception occurred
Traceback (most recent call last):
  File "/home/ichiro/factory-mockup/mockup.py", line 58, in send_data
    sock.connect((MODBUS_IP, MODBUS_PORT))
ConnectionRefusedError: [Errno 111] Connection refused
2023-06-18 17:43:08,261 INFO PID 12245 Playing video file 2.mp4
2023-06-18 17:43:08,344 ERROR PID 12245 Exception occurred
Traceback (most recent call last):
  File "/home/ichiro/factory-mockup/mockup.py", line 58, in send_data
    sock.connect((MODBUS_IP, MODBUS_PORT))
ConnectionRefusedError: [Errno 111] Connection refused
2023-06-18 17:43:09,358 INFO PID 12245 Playing video file 4.mp4
2023-06-18 17:43:09,446 ERROR PID 12245 Exception occurred
Traceback (most recent call last):
  File "/home/ichiro/factory-mockup/mockup.py", line 58, in send_data
    sock.connect((MODBUS_IP, MODBUS_PORT))
ConnectionRefusedError: [Errno 111] Connection refused
2023-06-18 17:43:10,261 INFO PID 12245 Playing video file 5.mp4
2023-06-18 17:43:10,391 ERROR PID 12245 Exception occurred
Traceback (most recent call last):
  File "/home/ichiro/factory-mockup/mockup.py", line 58, in send_data
    sock.connect((MODBUS_IP, MODBUS_PORT))
ConnectionRefusedError: [Errno 111] Connection refused
2023-06-18 17:43:11,405 INFO PID 12245 Playing video file 3.mp4
2023-06-18 17:43:11,490 ERROR PID 12245 Exception occurred
Traceback (most recent call last):
  File "/home/ichiro/factory-mockup/mockup.py", line 58, in send_data
    sock.connect((MODBUS_IP, MODBUS_PORT))
ConnectionRefusedError: [Errno 111] Connection refused
2023-06-18 17:43:12,399 INFO PID 12245 Playing video file 1.mp4
2023-06-18 17:43:12,465 ERROR PID 12245 Exception occurred
Traceback (most recent call last):
  File "/home/ichiro/factory-mockup/mockup.py", line 58, in send_data
    sock.connect((MODBUS_IP, MODBUS_PORT))
ConnectionRefusedError: [Errno 111] Connection refused
2023-06-18 17:43:13,273 INFO PID 12245 Playing video file 3.mp4
2023-06-18 17:43:13,350 ERROR PID 12245 Exception occurred
Traceback (most recent call last):
  File "/home/ichiro/factory-mockup/mockup.py", line 58, in send_data
    sock.connect((MODBUS_IP, MODBUS_PORT))
ConnectionRefusedError: [Errno 111] Connection refused
2023-06-18 17:43:15,270 INFO PID 12245 Playing video file 3.mp4
2023-06-18 17:43:15,343 ERROR PID 12245 Exception occurred
Traceback (most recent call last):
  File "/home/ichiro/factory-mockup/mockup.py", line 58, in send_data
    sock.connect((MODBUS_IP, MODBUS_PORT))
ConnectionRefusedError: [Errno 111] Connection refused
2023-06-18 17:43:16,355 INFO PID 12245 Playing video file 3.mp4
2023-06-18 17:43:16,431 ERROR PID 12245 Exception occurred
Traceback (most recent call last):
  File "/home/ichiro/factory-mockup/mockup.py", line 58, in send_data
    sock.connect((MODBUS_IP, MODBUS_PORT))
ConnectionRefusedError: [Errno 111] Connection refused
2023-06-18 17:43:17,239 INFO PID 12245 Playing video file 5.mp4
2023-06-18 17:43:17,316 ERROR PID 12245 Exception occurred
Traceback (most recent call last):
  File "/home/ichiro/factory-mockup/mockup.py", line 58, in send_data
    sock.connect((MODBUS_IP, MODBUS_PORT))
ConnectionRefusedError: [Errno 111] Connection refused
2023-06-18 17:43:18,227 INFO PID 12245 Playing video file 1.mp4
2023-06-18 17:43:18,309 ERROR PID 12245 Exception occurred
Traceback (most recent call last):
  File "/home/ichiro/factory-mockup/mockup.py", line 58, in send_data
    sock.connect((MODBUS_IP, MODBUS_PORT))
ConnectionRefusedError: [Errno 111] Connection refused
2023-06-18 17:43:20,024 INFO PID 12245 Playing video file 2.mp4
2023-06-18 17:43:20,133 ERROR PID 12245 Exception occurred
Traceback (most recent call last):
  File "/home/ichiro/factory-mockup/mockup.py", line 58, in send_data
    sock.connect((MODBUS_IP, MODBUS_PORT))
ConnectionRefusedError: [Errno 111] Connection refused
2023-06-18 17:43:21,848 INFO PID 12245 Playing video file 5.mp4
2023-06-18 17:43:21,932 ERROR PID 12245 Exception occurred
Traceback (most recent call last):
  File "/home/ichiro/factory-mockup/mockup.py", line 58, in send_data
    sock.connect((MODBUS_IP, MODBUS_PORT))
ConnectionRefusedError: [Errno 111] Connection refused
2023-06-18 17:43:23,244 INFO PID 12245 Playing video file 3.mp4
2023-06-18 17:43:23,357 ERROR PID 12245 Exception occurred
Traceback (most recent call last):
  File "/home/ichiro/factory-mockup/mockup.py", line 58, in send_data
    sock.connect((MODBUS_IP, MODBUS_PORT))
ConnectionRefusedError: [Errno 111] Connection refused
2023-06-18 17:43:24,374 INFO PID 12245 Playing video file 3.mp4
2023-06-18 17:43:24,460 ERROR PID 12245 Exception occurred
Traceback (most recent call last):
  File "/home/ichiro/factory-mockup/mockup.py", line 58, in send_data
    sock.connect((MODBUS_IP, MODBUS_PORT))
ConnectionRefusedError: [Errno 111] Connection refused
2023-06-18 17:43:25,372 INFO PID 12245 Playing video file 5.mp4
2023-06-18 17:43:25,445 ERROR PID 12245 Exception occurred
Traceback (most recent call last):
  File "/home/ichiro/factory-mockup/mockup.py", line 58, in send_data
    sock.connect((MODBUS_IP, MODBUS_PORT))
ConnectionRefusedError: [Errno 111] Connection refused
2023-06-18 17:43:27,160 INFO PID 12245 Playing video file 4.mp4
2023-06-18 17:43:27,280 ERROR PID 12245 Exception occurred
Traceback (most recent call last):
  File "/home/ichiro/factory-mockup/mockup.py", line 58, in send_data
    sock.connect((MODBUS_IP, MODBUS_PORT))
ConnectionRefusedError: [Errno 111] Connection refused
2023-06-18 17:43:30,608 INFO PID 12245 Playing video file 4.mp4
2023-06-18 17:43:30,693 ERROR PID 12245 Exception occurred
Traceback (most recent call last):
  File "/home/ichiro/factory-mockup/mockup.py", line 58, in send_data
    sock.connect((MODBUS_IP, MODBUS_PORT))
ConnectionRefusedError: [Errno 111] Connection refused
2023-06-18 17:43:31,606 INFO PID 12245 Playing video file 2.mp4
2023-06-18 17:43:31,796 ERROR PID 12245 Exception occurred
Traceback (most recent call last):
  File "/home/ichiro/factory-mockup/mockup.py", line 58, in send_data
    sock.connect((MODBUS_IP, MODBUS_PORT))
ConnectionRefusedError: [Errno 111] Connection refused
2023-06-18 17:43:32,713 INFO PID 12245 Playing video file 4.mp4
2023-06-18 17:43:32,783 ERROR PID 12245 Exception occurred
Traceback (most recent call last):
  File "/home/ichiro/factory-mockup/mockup.py", line 58, in send_data
    sock.connect((MODBUS_IP, MODBUS_PORT))
ConnectionRefusedError: [Errno 111] Connection refused
2023-06-18 17:43:33,695 INFO PID 12245 Playing video file 4.mp4
2023-06-18 17:43:33,783 ERROR PID 12245 Exception occurred
Traceback (most recent call last):
  File "/home/ichiro/factory-mockup/mockup.py", line 58, in send_data
    sock.connect((MODBUS_IP, MODBUS_PORT))
ConnectionRefusedError: [Errno 111] Connection refused
2023-06-18 17:43:37,108 INFO PID 12245 Playing video file 3.mp4
2023-06-18 17:43:37,197 ERROR PID 12245 Exception occurred
Traceback (most recent call last):
  File "/home/ichiro/factory-mockup/mockup.py", line 58, in send_data
    sock.connect((MODBUS_IP, MODBUS_PORT))
ConnectionRefusedError: [Errno 111] Connection refused
2023-06-18 17:43:38,913 INFO PID 12245 Playing video file 2.mp4
2023-06-18 17:43:38,997 ERROR PID 12245 Exception occurred
Traceback (most recent call last):
  File "/home/ichiro/factory-mockup/mockup.py", line 58, in send_data
    sock.connect((MODBUS_IP, MODBUS_PORT))
ConnectionRefusedError: [Errno 111] Connection refused
2023-06-18 17:43:40,206 INFO PID 12245 Playing video file 4.mp4
2023-06-18 17:43:40,309 ERROR PID 12245 Exception occurred
Traceback (most recent call last):
  File "/home/ichiro/factory-mockup/mockup.py", line 58, in send_data
    sock.connect((MODBUS_IP, MODBUS_PORT))
ConnectionRefusedError: [Errno 111] Connection refused
2023-06-18 17:43:41,114 INFO PID 12245 Playing video file 5.mp4
2023-06-18 17:43:41,190 ERROR PID 12245 Exception occurred
Traceback (most recent call last):
  File "/home/ichiro/factory-mockup/mockup.py", line 58, in send_data
    sock.connect((MODBUS_IP, MODBUS_PORT))
ConnectionRefusedError: [Errno 111] Connection refused
2023-06-18 17:43:42,106 INFO PID 12245 Playing video file 5.mp4
2023-06-18 17:43:42,169 ERROR PID 12245 Exception occurred
Traceback (most recent call last):
  File "/home/ichiro/factory-mockup/mockup.py", line 58, in send_data
    sock.connect((MODBUS_IP, MODBUS_PORT))
ConnectionRefusedError: [Errno 111] Connection refused
2023-06-18 17:43:42,987 INFO PID 12245 Playing video file 2.mp4
2023-06-18 17:43:43,058 ERROR PID 12245 Exception occurred
Traceback (most recent call last):
  File "/home/ichiro/factory-mockup/mockup.py", line 58, in send_data
    sock.connect((MODBUS_IP, MODBUS_PORT))
ConnectionRefusedError: [Errno 111] Connection refused
2023-06-18 17:43:44,771 INFO PID 12245 Playing video file 1.mp4
2023-06-18 17:43:44,845 ERROR PID 12245 Exception occurred
Traceback (most recent call last):
  File "/home/ichiro/factory-mockup/mockup.py", line 58, in send_data
    sock.connect((MODBUS_IP, MODBUS_PORT))
ConnectionRefusedError: [Errno 111] Connection refused
2023-06-18 17:43:45,652 INFO PID 12245 Playing video file 4.mp4
2023-06-18 17:43:45,742 ERROR PID 12245 Exception occurred
Traceback (most recent call last):
  File "/home/ichiro/factory-mockup/mockup.py", line 58, in send_data
    sock.connect((MODBUS_IP, MODBUS_PORT))
ConnectionRefusedError: [Errno 111] Connection refused
2023-06-18 17:43:47,151 INFO PID 12245 Playing video file 2.mp4
2023-06-18 17:43:47,235 ERROR PID 12245 Exception occurred
Traceback (most recent call last):
  File "/home/ichiro/factory-mockup/mockup.py", line 58, in send_data
    sock.connect((MODBUS_IP, MODBUS_PORT))
ConnectionRefusedError: [Errno 111] Connection refused
2023-06-18 17:43:48,046 INFO PID 12245 Playing video file 2.mp4
2023-06-18 17:43:48,127 ERROR PID 12245 Exception occurred
Traceback (most recent call last):
  File "/home/ichiro/factory-mockup/mockup.py", line 58, in send_data
    sock.connect((MODBUS_IP, MODBUS_PORT))
ConnectionRefusedError: [Errno 111] Connection refused
2023-06-18 17:43:48,936 INFO PID 12245 Playing video file 3.mp4
2023-06-18 17:43:49,026 ERROR PID 12245 Exception occurred
Traceback (most recent call last):
  File "/home/ichiro/factory-mockup/mockup.py", line 58, in send_data
    sock.connect((MODBUS_IP, MODBUS_PORT))
ConnectionRefusedError: [Errno 111] Connection refused
2023-06-18 17:43:49,843 INFO PID 12245 Playing video file 1.mp4
2023-06-18 17:43:49,916 ERROR PID 12245 Exception occurred
Traceback (most recent call last):
  File "/home/ichiro/factory-mockup/mockup.py", line 58, in send_data
    sock.connect((MODBUS_IP, MODBUS_PORT))
ConnectionRefusedError: [Errno 111] Connection refused
2023-06-18 17:43:51,733 INFO PID 12245 Playing video file 4.mp4
2023-06-18 17:43:51,811 ERROR PID 12245 Exception occurred
Traceback (most recent call last):
  File "/home/ichiro/factory-mockup/mockup.py", line 58, in send_data
    sock.connect((MODBUS_IP, MODBUS_PORT))
ConnectionRefusedError: [Errno 111] Connection refused
2023-06-18 17:43:52,622 INFO PID 12245 Playing video file 4.mp4
2023-06-18 17:43:52,712 ERROR PID 12245 Exception occurred
Traceback (most recent call last):
  File "/home/ichiro/factory-mockup/mockup.py", line 58, in send_data
    sock.connect((MODBUS_IP, MODBUS_PORT))
ConnectionRefusedError: [Errno 111] Connection refused
2023-06-18 17:43:54,432 INFO PID 12245 Playing video file 4.mp4
2023-06-18 17:43:54,514 ERROR PID 12245 Exception occurred
Traceback (most recent call last):
  File "/home/ichiro/factory-mockup/mockup.py", line 58, in send_data
    sock.connect((MODBUS_IP, MODBUS_PORT))
ConnectionRefusedError: [Errno 111] Connection refused
2023-06-18 17:43:55,428 INFO PID 12245 Playing video file 5.mp4
2023-06-18 17:43:55,504 ERROR PID 12245 Exception occurred
Traceback (most recent call last):
  File "/home/ichiro/factory-mockup/mockup.py", line 58, in send_data
    sock.connect((MODBUS_IP, MODBUS_PORT))
ConnectionRefusedError: [Errno 111] Connection refused
2023-06-18 17:44:00,843 INFO PID 12245 Playing video file 5.mp4
2023-06-18 17:44:00,911 ERROR PID 12245 Exception occurred
Traceback (most recent call last):
  File "/home/ichiro/factory-mockup/mockup.py", line 58, in send_data
    sock.connect((MODBUS_IP, MODBUS_PORT))
ConnectionRefusedError: [Errno 111] Connection refused
2023-06-18 17:44:01,725 INFO PID 12245 Playing video file 4.mp4
2023-06-18 17:44:01,790 ERROR PID 12245 Exception occurred
Traceback (most recent call last):
  File "/home/ichiro/factory-mockup/mockup.py", line 58, in send_data
    sock.connect((MODBUS_IP, MODBUS_PORT))
ConnectionRefusedError: [Errno 111] Connection refused
2023-06-18 17:44:02,604 INFO PID 12245 Playing video file 1.mp4
2023-06-18 17:44:02,662 ERROR PID 12245 Exception occurred
Traceback (most recent call last):
  File "/home/ichiro/factory-mockup/mockup.py", line 58, in send_data
    sock.connect((MODBUS_IP, MODBUS_PORT))
ConnectionRefusedError: [Errno 111] Connection refused
2023-06-18 17:44:03,873 INFO PID 12245 Playing video file 2.mp4
2023-06-18 17:44:03,959 ERROR PID 12245 Exception occurred
Traceback (most recent call last):
  File "/home/ichiro/factory-mockup/mockup.py", line 58, in send_data
    sock.connect((MODBUS_IP, MODBUS_PORT))
ConnectionRefusedError: [Errno 111] Connection refused
2023-06-18 17:44:04,267 INFO PID 12245 Playing video file 2.mp4
2023-06-18 17:44:04,441 ERROR PID 12245 Exception occurred
Traceback (most recent call last):
  File "/home/ichiro/factory-mockup/mockup.py", line 58, in send_data
    sock.connect((MODBUS_IP, MODBUS_PORT))
ConnectionRefusedError: [Errno 111] Connection refused
2023-06-18 17:44:04,649 INFO PID 12245 Playing video file 3.mp4
2023-06-18 17:44:04,804 ERROR PID 12245 Exception occurred
Traceback (most recent call last):
  File "/home/ichiro/factory-mockup/mockup.py", line 58, in send_data
    sock.connect((MODBUS_IP, MODBUS_PORT))
ConnectionRefusedError: [Errno 111] Connection refused
2023-06-18 17:44:05,009 INFO PID 12245 Playing video file 4.mp4
2023-06-18 17:44:05,073 ERROR PID 12245 Exception occurred
Traceback (most recent call last):
  File "/home/ichiro/factory-mockup/mockup.py", line 58, in send_data
    sock.connect((MODBUS_IP, MODBUS_PORT))
ConnectionRefusedError: [Errno 111] Connection refused
2023-06-18 17:44:05,479 INFO PID 12245 Playing video file 5.mp4
2023-06-18 17:44:05,568 ERROR PID 12245 Exception occurred
Traceback (most recent call last):
  File "/home/ichiro/factory-mockup/mockup.py", line 58, in send_data
    sock.connect((MODBUS_IP, MODBUS_PORT))
ConnectionRefusedError: [Errno 111] Connection refused
2023-06-18 17:44:05,878 INFO PID 12245 Playing video file 2.mp4
2023-06-18 17:44:06,026 ERROR PID 12245 Exception occurred
Traceback (most recent call last):
  File "/home/ichiro/factory-mockup/mockup.py", line 58, in send_data
    sock.connect((MODBUS_IP, MODBUS_PORT))
ConnectionRefusedError: [Errno 111] Connection refused
2023-06-18 17:44:06,257 INFO PID 12245 Playing video file 4.mp4
2023-06-18 17:44:06,356 ERROR PID 12245 Exception occurred
Traceback (most recent call last):
  File "/home/ichiro/factory-mockup/mockup.py", line 58, in send_data
    sock.connect((MODBUS_IP, MODBUS_PORT))
ConnectionRefusedError: [Errno 111] Connection refused
2023-06-18 17:44:06,661 INFO PID 12245 Playing video file 3.mp4
2023-06-18 17:44:06,820 ERROR PID 12245 Exception occurred
Traceback (most recent call last):
  File "/home/ichiro/factory-mockup/mockup.py", line 58, in send_data
    sock.connect((MODBUS_IP, MODBUS_PORT))
ConnectionRefusedError: [Errno 111] Connection refused
2023-06-18 17:44:07,026 INFO PID 12245 Playing video file 3.mp4
2023-06-18 17:44:07,113 ERROR PID 12245 Exception occurred
Traceback (most recent call last):
  File "/home/ichiro/factory-mockup/mockup.py", line 58, in send_data
    sock.connect((MODBUS_IP, MODBUS_PORT))
ConnectionRefusedError: [Errno 111] Connection refused
2023-06-18 17:44:07,418 INFO PID 12245 Playing video file 4.mp4
2023-06-18 17:44:07,579 ERROR PID 12245 Exception occurred
Traceback (most recent call last):
  File "/home/ichiro/factory-mockup/mockup.py", line 58, in send_data
    sock.connect((MODBUS_IP, MODBUS_PORT))
ConnectionRefusedError: [Errno 111] Connection refused
2023-06-18 17:44:07,886 INFO PID 12245 Playing video file 2.mp4
2023-06-18 17:44:08,076 ERROR PID 12245 Exception occurred
Traceback (most recent call last):
  File "/home/ichiro/factory-mockup/mockup.py", line 58, in send_data
    sock.connect((MODBUS_IP, MODBUS_PORT))
ConnectionRefusedError: [Errno 111] Connection refused
2023-06-18 17:44:08,284 INFO PID 12245 Playing video file 1.mp4
2023-06-18 17:44:08,392 ERROR PID 12245 Exception occurred
Traceback (most recent call last):
  File "/home/ichiro/factory-mockup/mockup.py", line 58, in send_data
    sock.connect((MODBUS_IP, MODBUS_PORT))
ConnectionRefusedError: [Errno 111] Connection refused
2023-06-18 17:44:08,699 INFO PID 12245 Playing video file 5.mp4
2023-06-18 17:44:08,889 ERROR PID 12245 Exception occurred
Traceback (most recent call last):
  File "/home/ichiro/factory-mockup/mockup.py", line 58, in send_data
    sock.connect((MODBUS_IP, MODBUS_PORT))
ConnectionRefusedError: [Errno 111] Connection refused
2023-06-18 17:44:09,195 INFO PID 12245 Playing video file 5.mp4
2023-06-18 17:44:09,376 ERROR PID 12245 Exception occurred
Traceback (most recent call last):
  File "/home/ichiro/factory-mockup/mockup.py", line 58, in send_data
    sock.connect((MODBUS_IP, MODBUS_PORT))
ConnectionRefusedError: [Errno 111] Connection refused
2023-06-18 17:44:09,590 INFO PID 12245 Playing video file 2.mp4
2023-06-18 17:44:09,673 ERROR PID 12245 Exception occurred
Traceback (most recent call last):
  File "/home/ichiro/factory-mockup/mockup.py", line 58, in send_data
    sock.connect((MODBUS_IP, MODBUS_PORT))
ConnectionRefusedError: [Errno 111] Connection refused
2023-06-18 17:44:10,085 INFO PID 12245 Playing video file 3.mp4
2023-06-18 17:44:10,173 ERROR PID 12245 Exception occurred
Traceback (most recent call last):
  File "/home/ichiro/factory-mockup/mockup.py", line 58, in send_data
    sock.connect((MODBUS_IP, MODBUS_PORT))
ConnectionRefusedError: [Errno 111] Connection refused
2023-06-18 17:44:10,378 INFO PID 12245 Playing video file 4.mp4
2023-06-18 17:44:10,461 ERROR PID 12245 Exception occurred
Traceback (most recent call last):
  File "/home/ichiro/factory-mockup/mockup.py", line 58, in send_data
    sock.connect((MODBUS_IP, MODBUS_PORT))
ConnectionRefusedError: [Errno 111] Connection refused
2023-06-18 17:44:10,867 INFO PID 12245 Playing video file 5.mp4
2023-06-18 17:44:10,939 ERROR PID 12245 Exception occurred
Traceback (most recent call last):
  File "/home/ichiro/factory-mockup/mockup.py", line 58, in send_data
    sock.connect((MODBUS_IP, MODBUS_PORT))
ConnectionRefusedError: [Errno 111] Connection refused
2023-06-18 17:44:11,246 INFO PID 12245 Playing video file 5.mp4
2023-06-18 17:44:11,385 ERROR PID 12245 Exception occurred
Traceback (most recent call last):
  File "/home/ichiro/factory-mockup/mockup.py", line 58, in send_data
    sock.connect((MODBUS_IP, MODBUS_PORT))
ConnectionRefusedError: [Errno 111] Connection refused
2023-06-18 17:44:11,693 INFO PID 12245 Playing video file 4.mp4
2023-06-18 17:44:11,870 ERROR PID 12245 Exception occurred
Traceback (most recent call last):
  File "/home/ichiro/factory-mockup/mockup.py", line 58, in send_data
    sock.connect((MODBUS_IP, MODBUS_PORT))
ConnectionRefusedError: [Errno 111] Connection refused
2023-06-18 17:44:12,181 INFO PID 12245 Playing video file 1.mp4
2023-06-18 17:44:12,337 ERROR PID 12245 Exception occurred
Traceback (most recent call last):
  File "/home/ichiro/factory-mockup/mockup.py", line 58, in send_data
    sock.connect((MODBUS_IP, MODBUS_PORT))
ConnectionRefusedError: [Errno 111] Connection refused
2023-06-18 17:44:12,651 INFO PID 12245 Playing video file 5.mp4
2023-06-18 17:44:12,821 ERROR PID 12245 Exception occurred
Traceback (most recent call last):
  File "/home/ichiro/factory-mockup/mockup.py", line 58, in send_data
    sock.connect((MODBUS_IP, MODBUS_PORT))
ConnectionRefusedError: [Errno 111] Connection refused
2023-06-18 17:44:14,537 INFO PID 12245 Playing video file 5.mp4
2023-06-18 17:44:14,658 ERROR PID 12245 Exception occurred
Traceback (most recent call last):
  File "/home/ichiro/factory-mockup/mockup.py", line 58, in send_data
    sock.connect((MODBUS_IP, MODBUS_PORT))
ConnectionRefusedError: [Errno 111] Connection refused
2023-06-18 17:44:15,267 INFO PID 12245 Playing video file 3.mp4
2023-06-18 17:44:15,349 ERROR PID 12245 Exception occurred
Traceback (most recent call last):
  File "/home/ichiro/factory-mockup/mockup.py", line 58, in send_data
    sock.connect((MODBUS_IP, MODBUS_PORT))
ConnectionRefusedError: [Errno 111] Connection refused
2023-06-18 17:44:16,076 INFO PID 12245 Playing video file 2.mp4
2023-06-18 17:44:16,167 ERROR PID 12245 Exception occurred
Traceback (most recent call last):
  File "/home/ichiro/factory-mockup/mockup.py", line 58, in send_data
    sock.connect((MODBUS_IP, MODBUS_PORT))
ConnectionRefusedError: [Errno 111] Connection refused
2023-06-18 17:44:16,881 INFO PID 12245 Playing video file 3.mp4
2023-06-18 17:44:16,948 ERROR PID 12245 Exception occurred
Traceback (most recent call last):
  File "/home/ichiro/factory-mockup/mockup.py", line 58, in send_data
    sock.connect((MODBUS_IP, MODBUS_PORT))
ConnectionRefusedError: [Errno 111] Connection refused
2023-06-18 17:44:17,657 INFO PID 12245 Playing video file 5.mp4
2023-06-18 17:44:17,742 ERROR PID 12245 Exception occurred
Traceback (most recent call last):
  File "/home/ichiro/factory-mockup/mockup.py", line 58, in send_data
    sock.connect((MODBUS_IP, MODBUS_PORT))
ConnectionRefusedError: [Errno 111] Connection refused
2023-06-18 17:44:19,367 INFO PID 12245 Playing video file 3.mp4
2023-06-18 17:44:19,450 ERROR PID 12245 Exception occurred
Traceback (most recent call last):
  File "/home/ichiro/factory-mockup/mockup.py", line 58, in send_data
    sock.connect((MODBUS_IP, MODBUS_PORT))
ConnectionRefusedError: [Errno 111] Connection refused
2023-06-18 17:44:20,165 INFO PID 12245 Playing video file 5.mp4
2023-06-18 17:44:20,237 ERROR PID 12245 Exception occurred
Traceback (most recent call last):
  File "/home/ichiro/factory-mockup/mockup.py", line 58, in send_data
    sock.connect((MODBUS_IP, MODBUS_PORT))
ConnectionRefusedError: [Errno 111] Connection refused
2023-06-18 17:44:22,959 INFO PID 12245 Playing video file 5.mp4
2023-06-18 17:44:23,039 ERROR PID 12245 Exception occurred
Traceback (most recent call last):
  File "/home/ichiro/factory-mockup/mockup.py", line 58, in send_data
    sock.connect((MODBUS_IP, MODBUS_PORT))
ConnectionRefusedError: [Errno 111] Connection refused
2023-06-18 17:44:23,747 INFO PID 12245 Playing video file 5.mp4
2023-06-18 17:44:23,814 ERROR PID 12245 Exception occurred
Traceback (most recent call last):
  File "/home/ichiro/factory-mockup/mockup.py", line 58, in send_data
    sock.connect((MODBUS_IP, MODBUS_PORT))
ConnectionRefusedError: [Errno 111] Connection refused
2023-06-18 17:44:24,528 INFO PID 12245 Playing video file 2.mp4
2023-06-18 17:44:24,625 ERROR PID 12245 Exception occurred
Traceback (most recent call last):
  File "/home/ichiro/factory-mockup/mockup.py", line 58, in send_data
    sock.connect((MODBUS_IP, MODBUS_PORT))
ConnectionRefusedError: [Errno 111] Connection refused
2023-06-18 17:44:25,344 INFO PID 12245 Playing video file 5.mp4
2023-06-18 17:44:25,419 ERROR PID 12245 Exception occurred
Traceback (most recent call last):
  File "/home/ichiro/factory-mockup/mockup.py", line 58, in send_data
    sock.connect((MODBUS_IP, MODBUS_PORT))
ConnectionRefusedError: [Errno 111] Connection refused
2023-06-18 17:44:26,130 INFO PID 12245 Playing video file 4.mp4
2023-06-18 17:44:26,197 ERROR PID 12245 Exception occurred
Traceback (most recent call last):
  File "/home/ichiro/factory-mockup/mockup.py", line 58, in send_data
    sock.connect((MODBUS_IP, MODBUS_PORT))
ConnectionRefusedError: [Errno 111] Connection refused
2023-06-18 17:44:27,012 INFO PID 12245 Playing video file 1.mp4
2023-06-18 17:44:27,091 ERROR PID 12245 Exception occurred
Traceback (most recent call last):
  File "/home/ichiro/factory-mockup/mockup.py", line 58, in send_data
    sock.connect((MODBUS_IP, MODBUS_PORT))
ConnectionRefusedError: [Errno 111] Connection refused
2023-06-18 17:44:27,800 INFO PID 12245 Playing video file 5.mp4
2023-06-18 17:44:27,880 ERROR PID 12245 Exception occurred
Traceback (most recent call last):
  File "/home/ichiro/factory-mockup/mockup.py", line 58, in send_data
    sock.connect((MODBUS_IP, MODBUS_PORT))
ConnectionRefusedError: [Errno 111] Connection refused
2023-06-18 17:44:28,487 INFO PID 12245 Playing video file 3.mp4
2023-06-18 17:44:28,569 ERROR PID 12245 Exception occurred
Traceback (most recent call last):
  File "/home/ichiro/factory-mockup/mockup.py", line 58, in send_data
    sock.connect((MODBUS_IP, MODBUS_PORT))
ConnectionRefusedError: [Errno 111] Connection refused
2023-06-18 17:45:04,601 INFO PID 13125 Start player
2023-06-18 17:45:20,911 INFO PID 13125 Playing video file 3.mp4
2023-06-18 17:45:21,026 ERROR PID 13125 Exception occurred
Traceback (most recent call last):
  File "/home/ichiro/factory-mockup/mockup.py", line 58, in send_data
    sock.connect((MODBUS_IP, MODBUS_PORT))
ConnectionRefusedError: [Errno 111] Connection refused
2023-06-18 17:45:22,956 INFO PID 13125 Playing video file 1.mp4
2023-06-18 17:45:23,074 ERROR PID 13125 Exception occurred
Traceback (most recent call last):
  File "/home/ichiro/factory-mockup/mockup.py", line 58, in send_data
    sock.connect((MODBUS_IP, MODBUS_PORT))
ConnectionRefusedError: [Errno 111] Connection refused
2023-06-18 17:45:23,885 INFO PID 13125 Playing video file 4.mp4
2023-06-18 17:45:23,960 ERROR PID 13125 Exception occurred
Traceback (most recent call last):
  File "/home/ichiro/factory-mockup/mockup.py", line 58, in send_data
    sock.connect((MODBUS_IP, MODBUS_PORT))
ConnectionRefusedError: [Errno 111] Connection refused
2023-06-18 17:45:24,724 INFO PID 13125 Playing video file 4.mp4
2023-06-18 17:45:24,823 ERROR PID 13125 Exception occurred
Traceback (most recent call last):
  File "/home/ichiro/factory-mockup/mockup.py", line 58, in send_data
    sock.connect((MODBUS_IP, MODBUS_PORT))
ConnectionRefusedError: [Errno 111] Connection refused
2023-06-18 17:45:26,700 INFO PID 13125 Playing video file 3.mp4
2023-06-18 17:45:26,790 ERROR PID 13125 Exception occurred
Traceback (most recent call last):
  File "/home/ichiro/factory-mockup/mockup.py", line 58, in send_data
    sock.connect((MODBUS_IP, MODBUS_PORT))
ConnectionRefusedError: [Errno 111] Connection refused
2023-06-18 17:45:27,553 INFO PID 13125 Playing video file 4.mp4
2023-06-18 17:45:27,654 ERROR PID 13125 Exception occurred
Traceback (most recent call last):
  File "/home/ichiro/factory-mockup/mockup.py", line 58, in send_data
    sock.connect((MODBUS_IP, MODBUS_PORT))
ConnectionRefusedError: [Errno 111] Connection refused
2023-06-18 17:45:28,469 INFO PID 13125 Playing video file 3.mp4
2023-06-18 17:45:28,538 ERROR PID 13125 Exception occurred
Traceback (most recent call last):
  File "/home/ichiro/factory-mockup/mockup.py", line 58, in send_data
    sock.connect((MODBUS_IP, MODBUS_PORT))
ConnectionRefusedError: [Errno 111] Connection refused
2023-06-18 17:45:29,405 INFO PID 13125 Playing video file 3.mp4
2023-06-18 17:45:29,487 ERROR PID 13125 Exception occurred
Traceback (most recent call last):
  File "/home/ichiro/factory-mockup/mockup.py", line 58, in send_data
    sock.connect((MODBUS_IP, MODBUS_PORT))
ConnectionRefusedError: [Errno 111] Connection refused
2023-06-18 17:45:30,354 INFO PID 13125 Playing video file 1.mp4
2023-06-18 17:45:30,435 ERROR PID 13125 Exception occurred
Traceback (most recent call last):
  File "/home/ichiro/factory-mockup/mockup.py", line 58, in send_data
    sock.connect((MODBUS_IP, MODBUS_PORT))
ConnectionRefusedError: [Errno 111] Connection refused
2023-06-18 17:45:31,198 INFO PID 13125 Playing video file 3.mp4
2023-06-18 17:45:31,274 ERROR PID 13125 Exception occurred
Traceback (most recent call last):
  File "/home/ichiro/factory-mockup/mockup.py", line 58, in send_data
    sock.connect((MODBUS_IP, MODBUS_PORT))
ConnectionRefusedError: [Errno 111] Connection refused
2023-06-18 17:45:33,008 INFO PID 13125 Playing video file 1.mp4
2023-06-18 17:45:33,086 ERROR PID 13125 Exception occurred
Traceback (most recent call last):
  File "/home/ichiro/factory-mockup/mockup.py", line 58, in send_data
    sock.connect((MODBUS_IP, MODBUS_PORT))
ConnectionRefusedError: [Errno 111] Connection refused
2023-06-18 17:45:33,849 INFO PID 13125 Playing video file 4.mp4
2023-06-18 17:45:33,916 ERROR PID 13125 Exception occurred
Traceback (most recent call last):
  File "/home/ichiro/factory-mockup/mockup.py", line 58, in send_data
    sock.connect((MODBUS_IP, MODBUS_PORT))
ConnectionRefusedError: [Errno 111] Connection refused
2023-06-18 17:47:54,915 INFO PID 13361 Start player
2023-06-18 17:48:10,629 INFO PID 13361 Playing video file 3.mp4
2023-06-18 17:48:10,763 ERROR PID 13361 Exception occurred
Traceback (most recent call last):
  File "/home/ichiro/factory-mockup/mockup.py", line 58, in send_data
    sock.connect((MODBUS_IP, MODBUS_PORT))
ConnectionRefusedError: [Errno 111] Connection refused
2023-06-18 17:48:11,835 INFO PID 13361 Playing video file 4.mp4
2023-06-18 17:48:11,907 ERROR PID 13361 Exception occurred
Traceback (most recent call last):
  File "/home/ichiro/factory-mockup/mockup.py", line 58, in send_data
    sock.connect((MODBUS_IP, MODBUS_PORT))
ConnectionRefusedError: [Errno 111] Connection refused
2023-06-18 17:48:12,822 INFO PID 13361 Playing video file 3.mp4
2023-06-18 17:48:12,895 ERROR PID 13361 Exception occurred
Traceback (most recent call last):
  File "/home/ichiro/factory-mockup/mockup.py", line 58, in send_data
    sock.connect((MODBUS_IP, MODBUS_PORT))
ConnectionRefusedError: [Errno 111] Connection refused
2023-06-18 17:48:13,821 INFO PID 13361 Playing video file 5.mp4
2023-06-18 17:48:13,895 ERROR PID 13361 Exception occurred
Traceback (most recent call last):
  File "/home/ichiro/factory-mockup/mockup.py", line 58, in send_data
    sock.connect((MODBUS_IP, MODBUS_PORT))
ConnectionRefusedError: [Errno 111] Connection refused
2023-06-18 17:48:14,969 INFO PID 13361 Playing video file 5.mp4
2023-06-18 17:48:15,084 ERROR PID 13361 Exception occurred
Traceback (most recent call last):
  File "/home/ichiro/factory-mockup/mockup.py", line 58, in send_data
    sock.connect((MODBUS_IP, MODBUS_PORT))
ConnectionRefusedError: [Errno 111] Connection refused
2023-06-18 17:48:15,846 INFO PID 13361 Playing video file 4.mp4
2023-06-18 17:48:15,920 ERROR PID 13361 Exception occurred
Traceback (most recent call last):
  File "/home/ichiro/factory-mockup/mockup.py", line 58, in send_data
    sock.connect((MODBUS_IP, MODBUS_PORT))
ConnectionRefusedError: [Errno 111] Connection refused
2023-06-18 17:48:16,784 INFO PID 13361 Playing video file 2.mp4
2023-06-18 17:48:16,850 ERROR PID 13361 Exception occurred
Traceback (most recent call last):
  File "/home/ichiro/factory-mockup/mockup.py", line 58, in send_data
    sock.connect((MODBUS_IP, MODBUS_PORT))
ConnectionRefusedError: [Errno 111] Connection refused
2023-06-18 17:48:17,717 INFO PID 13361 Playing video file 5.mp4
2023-06-18 17:48:17,785 ERROR PID 13361 Exception occurred
Traceback (most recent call last):
  File "/home/ichiro/factory-mockup/mockup.py", line 58, in send_data
    sock.connect((MODBUS_IP, MODBUS_PORT))
ConnectionRefusedError: [Errno 111] Connection refused
2023-06-18 17:48:18,659 INFO PID 13361 Playing video file 3.mp4
2023-06-18 17:48:18,733 ERROR PID 13361 Exception occurred
Traceback (most recent call last):
  File "/home/ichiro/factory-mockup/mockup.py", line 58, in send_data
    sock.connect((MODBUS_IP, MODBUS_PORT))
ConnectionRefusedError: [Errno 111] Connection refused
2023-06-18 17:48:19,550 INFO PID 13361 Playing video file 1.mp4
2023-06-18 17:48:19,637 ERROR PID 13361 Exception occurred
Traceback (most recent call last):
  File "/home/ichiro/factory-mockup/mockup.py", line 58, in send_data
    sock.connect((MODBUS_IP, MODBUS_PORT))
ConnectionRefusedError: [Errno 111] Connection refused
2023-06-18 17:48:20,451 INFO PID 13361 Playing video file 4.mp4
2023-06-18 17:48:20,604 ERROR PID 13361 Exception occurred
Traceback (most recent call last):
  File "/home/ichiro/factory-mockup/mockup.py", line 58, in send_data
    sock.connect((MODBUS_IP, MODBUS_PORT))
ConnectionRefusedError: [Errno 111] Connection refused
2023-06-18 17:48:21,424 INFO PID 13361 Playing video file 4.mp4
2023-06-18 17:48:21,516 ERROR PID 13361 Exception occurred
Traceback (most recent call last):
  File "/home/ichiro/factory-mockup/mockup.py", line 58, in send_data
    sock.connect((MODBUS_IP, MODBUS_PORT))
ConnectionRefusedError: [Errno 111] Connection refused
2023-06-18 17:48:22,229 INFO PID 13361 Playing video file 5.mp4
2023-06-18 17:48:22,301 ERROR PID 13361 Exception occurred
Traceback (most recent call last):
  File "/home/ichiro/factory-mockup/mockup.py", line 58, in send_data
    sock.connect((MODBUS_IP, MODBUS_PORT))
ConnectionRefusedError: [Errno 111] Connection refused
2023-06-18 17:48:23,174 INFO PID 13361 Playing video file 4.mp4
2023-06-18 17:48:23,245 ERROR PID 13361 Exception occurred
Traceback (most recent call last):
  File "/home/ichiro/factory-mockup/mockup.py", line 58, in send_data
    sock.connect((MODBUS_IP, MODBUS_PORT))
ConnectionRefusedError: [Errno 111] Connection refused
2023-06-18 17:50:30,903 INFO PID 13361 Playing video file 3.mp4
2023-06-18 17:50:31,005 ERROR PID 13361 Exception occurred
Traceback (most recent call last):
  File "/home/ichiro/factory-mockup/mockup.py", line 58, in send_data
    sock.connect((MODBUS_IP, MODBUS_PORT))
ConnectionRefusedError: [Errno 111] Connection refused
2023-06-18 17:50:32,882 INFO PID 13361 Playing video file 1.mp4
2023-06-18 17:50:32,957 ERROR PID 13361 Exception occurred
Traceback (most recent call last):
  File "/home/ichiro/factory-mockup/mockup.py", line 58, in send_data
    sock.connect((MODBUS_IP, MODBUS_PORT))
ConnectionRefusedError: [Errno 111] Connection refused
2023-06-18 17:50:33,012 INFO PID 13361 Playing video file 4.mp4
2023-06-18 17:50:33,202 ERROR PID 13361 Exception occurred
Traceback (most recent call last):
  File "/home/ichiro/factory-mockup/mockup.py", line 58, in send_data
    sock.connect((MODBUS_IP, MODBUS_PORT))
ConnectionRefusedError: [Errno 111] Connection refused
2023-06-18 17:50:33,962 INFO PID 13361 Playing video file 5.mp4
2023-06-18 17:50:34,045 ERROR PID 13361 Exception occurred
Traceback (most recent call last):
  File "/home/ichiro/factory-mockup/mockup.py", line 58, in send_data
    sock.connect((MODBUS_IP, MODBUS_PORT))
ConnectionRefusedError: [Errno 111] Connection refused
2023-06-18 17:50:34,759 INFO PID 13361 Playing video file 5.mp4
2023-06-18 17:50:34,834 ERROR PID 13361 Exception occurred
Traceback (most recent call last):
  File "/home/ichiro/factory-mockup/mockup.py", line 58, in send_data
    sock.connect((MODBUS_IP, MODBUS_PORT))
ConnectionRefusedError: [Errno 111] Connection refused
2023-06-18 17:50:34,893 INFO PID 13361 Playing video file 4.mp4
2023-06-18 17:50:35,085 ERROR PID 13361 Exception occurred
Traceback (most recent call last):
  File "/home/ichiro/factory-mockup/mockup.py", line 58, in send_data
    sock.connect((MODBUS_IP, MODBUS_PORT))
ConnectionRefusedError: [Errno 111] Connection refused
2023-06-18 17:50:35,849 INFO PID 13361 Playing video file 2.mp4
2023-06-18 17:50:35,937 ERROR PID 13361 Exception occurred
Traceback (most recent call last):
  File "/home/ichiro/factory-mockup/mockup.py", line 58, in send_data
    sock.connect((MODBUS_IP, MODBUS_PORT))
ConnectionRefusedError: [Errno 111] Connection refused
2023-06-18 18:30:47,367 INFO PID 13361 Playing video file 2.mp4
2023-06-18 18:30:47,443 ERROR PID 13361 Exception occurred
Traceback (most recent call last):
  File "/home/ichiro/factory-mockup/mockup.py", line 58, in send_data
    sock.connect((MODBUS_IP, MODBUS_PORT))
ConnectionRefusedError: [Errno 111] Connection refused
2023-06-18 18:30:47,498 INFO PID 13361 Playing video file 5.mp4
2023-06-18 18:30:47,648 ERROR PID 13361 Exception occurred
Traceback (most recent call last):
  File "/home/ichiro/factory-mockup/mockup.py", line 58, in send_data
    sock.connect((MODBUS_IP, MODBUS_PORT))
ConnectionRefusedError: [Errno 111] Connection refused
2023-06-18 18:30:51,057 INFO PID 13361 Playing video file 4.mp4
2023-06-18 18:30:51,152 ERROR PID 13361 Exception occurred
Traceback (most recent call last):
  File "/home/ichiro/factory-mockup/mockup.py", line 58, in send_data
    sock.connect((MODBUS_IP, MODBUS_PORT))
ConnectionRefusedError: [Errno 111] Connection refused
2023-06-18 18:30:51,206 INFO PID 13361 Playing video file 3.mp4
2023-06-18 18:30:51,334 ERROR PID 13361 Exception occurred
Traceback (most recent call last):
  File "/home/ichiro/factory-mockup/mockup.py", line 58, in send_data
    sock.connect((MODBUS_IP, MODBUS_PORT))
ConnectionRefusedError: [Errno 111] Connection refused
2023-06-18 18:30:52,452 INFO PID 13361 Playing video file 3.mp4
2023-06-18 18:30:52,526 ERROR PID 13361 Exception occurred
Traceback (most recent call last):
  File "/home/ichiro/factory-mockup/mockup.py", line 58, in send_data
    sock.connect((MODBUS_IP, MODBUS_PORT))
ConnectionRefusedError: [Errno 111] Connection refused
2023-06-18 18:30:52,588 INFO PID 13361 Playing video file 4.mp4
2023-06-18 18:30:52,781 ERROR PID 13361 Exception occurred
Traceback (most recent call last):
  File "/home/ichiro/factory-mockup/mockup.py", line 58, in send_data
    sock.connect((MODBUS_IP, MODBUS_PORT))
ConnectionRefusedError: [Errno 111] Connection refused
2023-06-18 18:30:57,337 INFO PID 13361 Playing video file 2.mp4
2023-06-18 18:30:57,423 ERROR PID 13361 Exception occurred
Traceback (most recent call last):
  File "/home/ichiro/factory-mockup/mockup.py", line 58, in send_data
    sock.connect((MODBUS_IP, MODBUS_PORT))
ConnectionRefusedError: [Errno 111] Connection refused
2023-06-18 18:30:57,482 INFO PID 13361 Playing video file 1.mp4
2023-06-18 18:30:57,648 ERROR PID 13361 Exception occurred
Traceback (most recent call last):
  File "/home/ichiro/factory-mockup/mockup.py", line 58, in send_data
    sock.connect((MODBUS_IP, MODBUS_PORT))
ConnectionRefusedError: [Errno 111] Connection refused
2023-06-18 18:31:00,694 INFO PID 13361 Playing video file 3.mp4
2023-06-18 18:31:00,772 ERROR PID 13361 Exception occurred
Traceback (most recent call last):
  File "/home/ichiro/factory-mockup/mockup.py", line 58, in send_data
    sock.connect((MODBUS_IP, MODBUS_PORT))
ConnectionRefusedError: [Errno 111] Connection refused
2023-06-18 18:31:00,829 INFO PID 13361 Playing video file 1.mp4
2023-06-18 18:31:00,988 ERROR PID 13361 Exception occurred
Traceback (most recent call last):
  File "/home/ichiro/factory-mockup/mockup.py", line 58, in send_data
    sock.connect((MODBUS_IP, MODBUS_PORT))
ConnectionRefusedError: [Errno 111] Connection refused
2023-06-18 18:31:01,800 INFO PID 13361 Playing video file 2.mp4
2023-06-18 18:31:01,891 ERROR PID 13361 Exception occurred
Traceback (most recent call last):
  File "/home/ichiro/factory-mockup/mockup.py", line 58, in send_data
    sock.connect((MODBUS_IP, MODBUS_PORT))
ConnectionRefusedError: [Errno 111] Connection refused
2023-06-18 18:31:03,058 INFO PID 13361 Playing video file 1.mp4
2023-06-18 18:31:03,093 ERROR PID 13361 Exception occurred
Traceback (most recent call last):
  File "/home/ichiro/factory-mockup/mockup.py", line 58, in send_data
    sock.connect((MODBUS_IP, MODBUS_PORT))
ConnectionRefusedError: [Errno 111] Connection refused
2023-06-18 18:32:10,473 INFO PID 13361 Playing video file 5.mp4
2023-06-18 18:32:10,511 ERROR PID 13361 Exception occurred
Traceback (most recent call last):
  File "/home/ichiro/factory-mockup/mockup.py", line 58, in send_data
    sock.connect((MODBUS_IP, MODBUS_PORT))
ConnectionRefusedError: [Errno 111] Connection refused
2023-06-18 18:32:10,564 INFO PID 13361 Playing video file 3.mp4
2023-06-18 18:32:10,711 ERROR PID 13361 Exception occurred
Traceback (most recent call last):
  File "/home/ichiro/factory-mockup/mockup.py", line 58, in send_data
    sock.connect((MODBUS_IP, MODBUS_PORT))
ConnectionRefusedError: [Errno 111] Connection refused
2023-06-18 18:32:12,443 INFO PID 13361 Playing video file 3.mp4
2023-06-18 18:32:12,524 ERROR PID 13361 Exception occurred
Traceback (most recent call last):
  File "/home/ichiro/factory-mockup/mockup.py", line 58, in send_data
    sock.connect((MODBUS_IP, MODBUS_PORT))
ConnectionRefusedError: [Errno 111] Connection refused
2023-06-18 18:32:12,581 INFO PID 13361 Playing video file 3.mp4
2023-06-18 18:32:12,734 ERROR PID 13361 Exception occurred
Traceback (most recent call last):
  File "/home/ichiro/factory-mockup/mockup.py", line 58, in send_data
    sock.connect((MODBUS_IP, MODBUS_PORT))
ConnectionRefusedError: [Errno 111] Connection refused
2023-06-18 18:32:14,257 INFO PID 13361 Playing video file 4.mp4
2023-06-18 18:32:14,368 ERROR PID 13361 Exception occurred
Traceback (most recent call last):
  File "/home/ichiro/factory-mockup/mockup.py", line 58, in send_data
    sock.connect((MODBUS_IP, MODBUS_PORT))
ConnectionRefusedError: [Errno 111] Connection refused
2023-06-18 18:35:46,876 INFO PID 13361 Playing video file 3.mp4
2023-06-18 18:35:46,920 ERROR PID 13361 Exception occurred
Traceback (most recent call last):
  File "/home/ichiro/factory-mockup/mockup.py", line 58, in send_data
    sock.connect((MODBUS_IP, MODBUS_PORT))
ConnectionRefusedError: [Errno 111] Connection refused
2023-06-18 18:41:02,851 INFO PID 13361 Playing video file 1.mp4
2023-06-18 18:41:02,883 ERROR PID 13361 Exception occurred
Traceback (most recent call last):
  File "/home/ichiro/factory-mockup/mockup.py", line 58, in send_data
    sock.connect((MODBUS_IP, MODBUS_PORT))
ConnectionRefusedError: [Errno 111] Connection refused
2023-06-18 18:44:49,342 INFO PID 13361 Playing video file 5.mp4
2023-06-18 18:44:49,469 ERROR PID 13361 Exception occurred
Traceback (most recent call last):
  File "/home/ichiro/factory-mockup/mockup.py", line 58, in send_data
    sock.connect((MODBUS_IP, MODBUS_PORT))
ConnectionRefusedError: [Errno 111] Connection refused
2023-06-18 18:44:52,779 INFO PID 13361 Playing video file 5.mp4
2023-06-18 18:44:52,875 ERROR PID 13361 Exception occurred
Traceback (most recent call last):
  File "/home/ichiro/factory-mockup/mockup.py", line 58, in send_data
    sock.connect((MODBUS_IP, MODBUS_PORT))
ConnectionRefusedError: [Errno 111] Connection refused
2023-06-18 18:44:52,933 INFO PID 13361 Playing video file 4.mp4
2023-06-18 18:44:52,998 ERROR PID 13361 Exception occurred
Traceback (most recent call last):
  File "/home/ichiro/factory-mockup/mockup.py", line 58, in send_data
    sock.connect((MODBUS_IP, MODBUS_PORT))
ConnectionRefusedError: [Errno 111] Connection refused
2023-06-18 18:44:53,051 INFO PID 13361 Playing video file 3.mp4
2023-06-18 18:44:53,150 ERROR PID 13361 Exception occurred
Traceback (most recent call last):
  File "/home/ichiro/factory-mockup/mockup.py", line 58, in send_data
    sock.connect((MODBUS_IP, MODBUS_PORT))
ConnectionRefusedError: [Errno 111] Connection refused
2023-06-18 18:44:54,943 INFO PID 13361 Playing video file 1.mp4
2023-06-18 18:44:55,028 ERROR PID 13361 Exception occurred
Traceback (most recent call last):
  File "/home/ichiro/factory-mockup/mockup.py", line 58, in send_data
    sock.connect((MODBUS_IP, MODBUS_PORT))
ConnectionRefusedError: [Errno 111] Connection refused
2023-06-18 18:44:55,086 INFO PID 13361 Playing video file 2.mp4
2023-06-18 18:44:55,287 ERROR PID 13361 Exception occurred
Traceback (most recent call last):
  File "/home/ichiro/factory-mockup/mockup.py", line 58, in send_data
    sock.connect((MODBUS_IP, MODBUS_PORT))
ConnectionRefusedError: [Errno 111] Connection refused
2023-06-18 18:44:56,456 INFO PID 13361 Playing video file 2.mp4
2023-06-18 18:44:56,634 ERROR PID 13361 Exception occurred
Traceback (most recent call last):
  File "/home/ichiro/factory-mockup/mockup.py", line 58, in send_data
    sock.connect((MODBUS_IP, MODBUS_PORT))
ConnectionRefusedError: [Errno 111] Connection refused
2023-06-18 18:44:56,698 INFO PID 13361 Playing video file 3.mp4
2023-06-18 18:44:56,825 ERROR PID 13361 Exception occurred
Traceback (most recent call last):
  File "/home/ichiro/factory-mockup/mockup.py", line 58, in send_data
    sock.connect((MODBUS_IP, MODBUS_PORT))
ConnectionRefusedError: [Errno 111] Connection refused
2023-06-18 18:44:58,601 INFO PID 13361 Playing video file 2.mp4
2023-06-18 18:44:58,676 ERROR PID 13361 Exception occurred
Traceback (most recent call last):
  File "/home/ichiro/factory-mockup/mockup.py", line 58, in send_data
    sock.connect((MODBUS_IP, MODBUS_PORT))
ConnectionRefusedError: [Errno 111] Connection refused
2023-06-18 18:44:58,735 INFO PID 13361 Playing video file 5.mp4
2023-06-18 18:44:58,826 ERROR PID 13361 Exception occurred
Traceback (most recent call last):
  File "/home/ichiro/factory-mockup/mockup.py", line 58, in send_data
    sock.connect((MODBUS_IP, MODBUS_PORT))
ConnectionRefusedError: [Errno 111] Connection refused
2023-06-18 18:52:58,773 INFO PID 13361 Playing video file 4.mp4
2023-06-18 18:52:58,847 ERROR PID 13361 Exception occurred
Traceback (most recent call last):
  File "/home/ichiro/factory-mockup/mockup.py", line 58, in send_data
    sock.connect((MODBUS_IP, MODBUS_PORT))
ConnectionRefusedError: [Errno 111] Connection refused
2023-06-18 18:53:00,123 INFO PID 13361 Playing video file 5.mp4
2023-06-18 18:53:00,337 ERROR PID 13361 Exception occurred
Traceback (most recent call last):
  File "/home/ichiro/factory-mockup/mockup.py", line 58, in send_data
    sock.connect((MODBUS_IP, MODBUS_PORT))
ConnectionRefusedError: [Errno 111] Connection refused
2023-06-18 18:53:03,378 INFO PID 13361 Playing video file 4.mp4
2023-06-18 18:53:03,447 ERROR PID 13361 Exception occurred
Traceback (most recent call last):
  File "/home/ichiro/factory-mockup/mockup.py", line 58, in send_data
    sock.connect((MODBUS_IP, MODBUS_PORT))
ConnectionRefusedError: [Errno 111] Connection refused
2023-06-18 18:53:04,768 INFO PID 13361 Playing video file 3.mp4
2023-06-18 18:53:04,859 ERROR PID 13361 Exception occurred
Traceback (most recent call last):
  File "/home/ichiro/factory-mockup/mockup.py", line 58, in send_data
    sock.connect((MODBUS_IP, MODBUS_PORT))
ConnectionRefusedError: [Errno 111] Connection refused
2023-06-18 18:53:05,829 INFO PID 13361 Playing video file 5.mp4
2023-06-18 18:53:05,914 ERROR PID 13361 Exception occurred
Traceback (most recent call last):
  File "/home/ichiro/factory-mockup/mockup.py", line 58, in send_data
    sock.connect((MODBUS_IP, MODBUS_PORT))
ConnectionRefusedError: [Errno 111] Connection refused
2023-06-18 18:53:06,730 INFO PID 13361 Playing video file 2.mp4
2023-06-18 18:53:06,803 ERROR PID 13361 Exception occurred
Traceback (most recent call last):
  File "/home/ichiro/factory-mockup/mockup.py", line 58, in send_data
    sock.connect((MODBUS_IP, MODBUS_PORT))
ConnectionRefusedError: [Errno 111] Connection refused
2023-06-18 18:54:51,777 INFO PID 13361 Playing video file 2.mp4
2023-06-18 18:54:51,862 ERROR PID 13361 Exception occurred
Traceback (most recent call last):
  File "/home/ichiro/factory-mockup/mockup.py", line 58, in send_data
    sock.connect((MODBUS_IP, MODBUS_PORT))
ConnectionRefusedError: [Errno 111] Connection refused
2023-06-18 18:54:55,127 INFO PID 13361 Playing video file 5.mp4
2023-06-18 18:54:55,208 ERROR PID 13361 Exception occurred
Traceback (most recent call last):
  File "/home/ichiro/factory-mockup/mockup.py", line 58, in send_data
    sock.connect((MODBUS_IP, MODBUS_PORT))
ConnectionRefusedError: [Errno 111] Connection refused
2023-06-18 18:54:55,264 INFO PID 13361 Playing video file 2.mp4
2023-06-18 18:54:55,469 ERROR PID 13361 Exception occurred
Traceback (most recent call last):
  File "/home/ichiro/factory-mockup/mockup.py", line 58, in send_data
    sock.connect((MODBUS_IP, MODBUS_PORT))
ConnectionRefusedError: [Errno 111] Connection refused
2023-06-18 18:54:56,179 INFO PID 13361 Playing video file 1.mp4
2023-06-18 18:54:56,274 ERROR PID 13361 Exception occurred
Traceback (most recent call last):
  File "/home/ichiro/factory-mockup/mockup.py", line 58, in send_data
    sock.connect((MODBUS_IP, MODBUS_PORT))
ConnectionRefusedError: [Errno 111] Connection refused
2023-06-18 18:54:56,331 INFO PID 13361 Playing video file 2.mp4
2023-06-18 18:54:56,433 ERROR PID 13361 Exception occurred
Traceback (most recent call last):
  File "/home/ichiro/factory-mockup/mockup.py", line 58, in send_data
    sock.connect((MODBUS_IP, MODBUS_PORT))
ConnectionRefusedError: [Errno 111] Connection refused
2023-06-18 18:54:57,153 INFO PID 13361 Playing video file 1.mp4
2023-06-18 18:54:57,241 ERROR PID 13361 Exception occurred
Traceback (most recent call last):
  File "/home/ichiro/factory-mockup/mockup.py", line 58, in send_data
    sock.connect((MODBUS_IP, MODBUS_PORT))
ConnectionRefusedError: [Errno 111] Connection refused
2023-06-18 18:54:58,225 INFO PID 13361 Playing video file 4.mp4
2023-06-18 18:54:58,353 ERROR PID 13361 Exception occurred
Traceback (most recent call last):
  File "/home/ichiro/factory-mockup/mockup.py", line 58, in send_data
    sock.connect((MODBUS_IP, MODBUS_PORT))
ConnectionRefusedError: [Errno 111] Connection refused
2023-06-18 20:12:21,310 INFO PID 13361 Playing video file 1.mp4
2023-06-18 20:12:21,402 ERROR PID 13361 Exception occurred
Traceback (most recent call last):
  File "/home/ichiro/factory-mockup/mockup.py", line 58, in send_data
    sock.connect((MODBUS_IP, MODBUS_PORT))
ConnectionRefusedError: [Errno 111] Connection refused
2023-06-18 20:44:52,522 INFO PID 13361 Playing video file 4.mp4
2023-06-18 20:44:52,601 ERROR PID 13361 Exception occurred
Traceback (most recent call last):
  File "/home/ichiro/factory-mockup/mockup.py", line 58, in send_data
    sock.connect((MODBUS_IP, MODBUS_PORT))
ConnectionRefusedError: [Errno 111] Connection refused
2023-06-18 20:44:52,658 INFO PID 13361 Playing video file 5.mp4
2023-06-18 20:44:52,762 ERROR PID 13361 Exception occurred
Traceback (most recent call last):
  File "/home/ichiro/factory-mockup/mockup.py", line 58, in send_data
    sock.connect((MODBUS_IP, MODBUS_PORT))
ConnectionRefusedError: [Errno 111] Connection refused
2023-06-18 20:45:20,912 INFO PID 13361 Playing video file 5.mp4
2023-06-18 20:45:21,015 ERROR PID 13361 Exception occurred
Traceback (most recent call last):
  File "/home/ichiro/factory-mockup/mockup.py", line 58, in send_data
    sock.connect((MODBUS_IP, MODBUS_PORT))
ConnectionRefusedError: [Errno 111] Connection refused
2023-06-18 20:45:21,069 INFO PID 13361 Playing video file 2.mp4
